Workbook
Name ExclList: Inputs!$B$26:$B$30
Name FX_Ccy: Inputs!$B$16:$B$23
Name FX_Rate: Inputs!$C$16:$C$23
Name N_Co: Universe!$G$2
Name PriceDiv: Inputs!$C$13
Name ScreenDate: Inputs!$C$11

Sheet Inputs
A1: Inputs
B3: Metric | C3: Weight | D3: Better when
B4: EV/EBIT | C4: 0.3 | D4: Lower
B5: FCF yield | C5: 0.25 | D5: Higher
B6: Cash Conversion | C6: 0.2 | D6: Higher
B7: Net Debt/EBITDA | C7: 0.15 | D7: Lower
B8: Revenue CAGR | C8: 0.1 | D8: Higher
B9: Total | C9: =SUM(C4:C8) -> 1
B11: Screen Date | C11: 46295
B12: Price quoted in, | C12: Pounds
B13: Price divisor | C13: =IF(C12="Pence",100,1) -> 1
B15: Currency | C15: GBP per 1 unit
B16: GBP | C16: 1
B17: USD | C17: 0.7528
B18: EUR | C18: 0.855
B25: Excluded Sectors
B26: Financials
B27: Real Estate

Sheet Universe
F2: Included: | G2: =COUNTIF(G6:G305,"Include") -> 119
A5: Ticker | B5: Company | C5: ISIN | D5: Sector | E5: Auto status | F5: Override | G5: Final Status | H5: Notes
A6: 3IN | B6: 3i Infrastructure | C6: JE00BF5FX167 | D6: Financials | E6: =IF($A6="","",IF(COUNTIF(ExclList,$D6)>0,"Exclude","Include")) -> Exclude | G6: =IF($A6="","",IF($F6<>"",$F6,$E6)) -> Exclude
A7: FOUR | B7: 4imprint | C7: GB0006640972 | D7: Consumer Discretionary | E7: =IF($A7="","",IF(COUNTIF(ExclList,$D7)>0,"Exclude","Include")) -> Include | G7: =IF($A7="","",IF($F7<>"",$F7,$E7)) -> Include
A8: AAS | B8: Aberdeen Asia Focus | C8: GB00BMF19B58 | D8: Financials | E8: =IF($A8="","",IF(COUNTIF(ExclList,$D8)>0,"Exclude","Include")) -> Exclude | G8: =IF($A8="","",IF($F8<>"",$F8,$E8)) -> Exclude
A9: ASL | B9: Aberforth Smaller Companies Trust | C9: GB0000066554 | D9: Financials | E9: =IF($A9="","",IF(COUNTIF(ExclList,$D9)>0,"Exclude","Include")) -> Exclude | G9: =IF($A9="","",IF($F9<>"",$F9,$E9)) -> Exclude
A10: AEP | B10: AEP Plantations | C10: GB00BWPD4D87 | D10: Consumer Staples | E10: =IF($A10="","",IF(COUNTIF(ExclList,$D10)>0,"Exclude","Include")) -> Include | G10: =IF($A10="","",IF($F10<>"",$F10,$E10)) -> Include
A11: ALFA | B11: Alfa Financial Software | C11: GB00BDHXPG30 | D11: Technology | E11: =IF($A11="","",IF(COUNTIF(ExclList,$D11)>0,"Exclude","Include")) -> Include | G11: =IF($A11="","",IF($F11<>"",$F11,$E11)) -> Include
A12: ATT | B12: Allianz Technology Trust | C12: GB00BNG2M159 | D12: Financials | E12: =IF($A12="","",IF(COUNTIF(ExclList,$D12)>0,"Exclude","Include")) -> Exclude | G12: =IF($A12="","",IF($F12<>"",$F12,$E12)) -> Exclude
A13: AMRQ | B13: Amaroq | D13: Basic Materials | E13: =IF($A13="","",IF(COUNTIF(ExclList,$D13)>0,"Exclude","Include")) -> Include | F13: Exclude | G13: =IF($A13="","",IF($F13<>"",$F13,$E13)) -> Exclude
A14: AO | B14: AO World | C14: GB00BJTNFH41 | D14: Consumer Discretionary | E14: =IF($A14="","",IF(COUNTIF(ExclList,$D14)>0,"Exclude","Include")) -> Include | G14: =IF($A14="","",IF($F14<>"",$F14,$E14)) -> Include
A15: APN | B15: Applied Nutrition | C15: GB00BPVDXX64 | D15: Consumer Staples | E15: =IF($A15="","",IF(COUNTIF(ExclList,$D15)>0,"Exclude","Include")) -> Include | G15: =IF($A15="","",IF($F15<>"",$F15,$E15)) -> Include
A16: ASHM | B16: Ashmore Group | C16: GB00B132NW22 | D16: Financials | E16: =IF($A16="","",IF(COUNTIF(ExclList,$D16)>0,"Exclude","Include")) -> Exclude | G16: =IF($A16="","",IF($F16<>"",$F16,$E16)) -> Exclude
A17: AIE | B17: Ashoka India Equity Investment Trust | C17: GB00BF50VS41 | D17: Financials | E17: =IF($A17="","",IF(COUNTIF(ExclList,$D17)>0,"Exclude","Include")) -> Exclude | G17: =IF($A17="","",IF($F17<>"",$F17,$E17)) -> Exclude
A18: ASC | B18: ASOS | C18: GB0030927254 | D18: Consumer Discretionary | E18: =IF($A18="","",IF(COUNTIF(ExclList,$D18)>0,"Exclude","Include")) -> Include | G18: =IF($A18="","",IF($F18<>"",$F18,$E18)) -> Include
A19: ATYM | B19: Atalaya Mining | C19: CY0106002112 | D19: Basic Materials | E19: =IF($A19="","",IF(COUNTIF(ExclList,$D19)>0,"Exclude","Include")) -> Include | G19: =IF($A19="","",IF($F19<>"",$F19,$E19)) -> Include
A20: ATG | B20: Auction Technology Group | C20: GB00BMVQDZ64 | D20: Technology | E20: =IF($A20="","",IF(COUNTIF(ExclList,$D20)>0,"Exclude","Include")) -> Include | G20: =IF($A20="","",IF($F20<>"",$F20,$E20)) -> Include
A21: AGT | B21: AVI Global Trust | C21: GB00BLH3CY60 | D21: Financials | E21: =IF($A21="","",IF(COUNTIF(ExclList,$D21)>0,"Exclude","Include")) -> Exclude | G21: =IF($A21="","",IF($F21<>"",$F21,$E21)) -> Exclude
A22: AVON | B22: Avon Technologies | C22: GB0000667013 | D22: Industrials | E22: =IF($A22="","",IF(COUNTIF(ExclList,$D22)>0,"Exclude","Include")) -> Include | G22: =IF($A22="","",IF($F22<>"",$F22,$E22)) -> Include
A23: BME | B23: B&M | C23: JE00BVSYJW51 | D23: Consumer Discretionary | E23: =IF($A23="","",IF(COUNTIF(ExclList,$D23)>0,"Exclude","Include")) -> Include | G23: =IF($A23="","",IF($F23<>"",$F23,$E23)) -> Include
A24: BGFD | B24: Baillie Gifford Japan Trust | C24: GB0000485838 | D24: Financials | E24: =IF($A24="","",IF(COUNTIF(ExclList,$D24)>0,"Exclude","Include")) -> Exclude | G24: =IF($A24="","",IF($F24<>"",$F24,$E24)) -> Exclude
A25: USA | B25: Baillie Gifford US Growth Trust | C25: GB00BDFGHW41 | D25: Financials | E25: =IF($A25="","",IF(COUNTIF(ExclList,$D25)>0,"Exclude","Include")) -> Exclude | G25: =IF($A25="","",IF($F25<>"",$F25,$E25)) -> Exclude
... A28: BAG | B28: A.G. Barr | C28: GB00B6XZKY75 | D28: Consumer Staples | E28: =IF($A28="","",IF(COUNTIF(ExclList,$D28)>0,"Exclude","Include")) -> Include | G28: =IF($A28="","",IF($F28<>"",$F28,$E28)) -> Include
A29: AJB | B29: AJ Bell | C29: GB00BFZNLB60 | D29: Financials | E29: =IF($A29="","",IF(COUNTIF(ExclList,$D29)>0,"Exclude","Include")) -> Exclude | F29: Exclude | G29: =IF($A29="","",IF($F29<>"",$F29,$E29)) -> Exclude
A30: BWY | B30: Bellway | C30: GB0000904986 | D30: Consumer Discretionary | E30: =IF($A30="","",IF(COUNTIF(ExclList,$D30)>0,"Exclude","Include")) -> Include | G30: =IF($A30="","",IF($F30<>"",$F30,$E30)) -> Include
A31: BKG | B31: Berkeley Group Holdings | C31: GB00BP0RGD03 | D31: Consumer Discretionary | E31: =IF($A31="","",IF(COUNTIF(ExclList,$D31)>0,"Exclude","Include")) -> Include | G31: =IF($A31="","",IF($F31<>"",$F31,$E31)) -> Include
A32: BHMG | B32: BH Macro | C32: GG00BQBFY362 | D32: Financials | E32: =IF($A32="","",IF(COUNTIF(ExclList,$D32)>0,"Exclude","Include")) -> Exclude | G32: =IF($A32="","",IF($F32<>"",$F32,$E32)) -> Exclude
A33: BYG | B33: Big Yellow Group | C33: GB0002869419 | D33: Real Estate | E33: =IF($A33="","",IF(COUNTIF(ExclList,$D33)>0,"Exclude","Include")) -> Exclude | G33: =IF($A33="","",IF($F33<>"",$F33,$E33)) -> Exclude
A34: BPCR | B34: Biopharma Credit | C34: GB00BDGKMY29 | D34: Financials | E34: =IF($A34="","",IF(COUNTIF(ExclList,$D34)>0,"Exclude","Include")) -> Exclude | G34: =IF($A34="","",IF($F34<>"",$F34,$E34)) -> Exclude
A35: BRGE | B35: BlackRock Greater Europe Investment Trust | C35: GB00B01RDH75 | D35: Financials | E35: =IF($A35="","",IF(COUNTIF(ExclList,$D35)>0,"Exclude","Include")) -> Exclude | G35: =IF($A35="","",IF($F35<>"",$F35,$E35)) -> Exclude
A36: BRSC | B36: BlackRock Smaller Companies Trust | C36: GB00BWQGKH23 | D36: Financials | E36: =IF($A36="","",IF(COUNTIF(ExclList,$D36)>0,"Exclude","Include")) -> Exclude | G36: =IF($A36="","",IF($F36<>"",$F36,$E36)) -> Exclude
A37: BRWM | B37: BlackRock World Mining Trust | C37: GB0005774855 | D37: Financials | E37: =IF($A37="","",IF(COUNTIF(ExclList,$D37)>0,"Exclude","Include")) -> Exclude | G37: =IF($A37="","",IF($F37<>"",$F37,$E37)) -> Exclude
A38: BMY | B38: Bloomsbury Publishing | C38: GB0033147751 | D38: Consumer Discretionary | E38: =IF($A38="","",IF(COUNTIF(ExclList,$D38)>0,"Exclude","Include")) -> Include | G38: =IF($A38="","",IF($F38<>"",$F38,$E38)) -> Include
A39: BOY | B39: Bodycote | C39: GB00B3FLWH99 | D39: Industrials | E39: =IF($A39="","",IF(COUNTIF(ExclList,$D39)>0,"Exclude","Include")) -> Include | G39: =IF($A39="","",IF($F39<>"",$F39,$E39)) -> Include
A40: BREE | B40: Breedon Group | C40: GB00BM8NFJ84 | D40: Industrials | E40: =IF($A40="","",IF(COUNTIF(ExclList,$D40)>0,"Exclude","Include")) -> Include | G40: =IF($A40="","",IF($F40<>"",$F40,$E40)) -> Include
A41: BPT | B41: Bridgepoint Group | C41: GB00BND88V85 | D41: Financials | E41: =IF($A41="","",IF(COUNTIF(ExclList,$D41)>0,"Exclude","Include")) -> Exclude | G41: =IF($A41="","",IF($F41<>"",$F41,$E41)) -> Exclude
A42: BUT | B42: Brunner Investment Trust | C42: GB0001490449 | D42: Financials | E42: =IF($A42="","",IF(COUNTIF(ExclList,$D42)>0,"Exclude","Include")) -> Exclude | G42: =IF($A42="","",IF($F42<>"",$F42,$E42)) -> Exclude
A43: BYIT | B43: Bytes Technology Group | C43: GB00BMH18Q19 | D43: Technology | E43: =IF($A43="","",IF(COUNTIF(ExclList,$D43)>0,"Exclude","Include")) -> Include | F43: Include | G43: =IF($A43="","",IF($F43<>"",$F43,$E43)) -> Include
A44: CLDN | B44: Caledonia Investments | C44: GB00BTNQ8K38 | D44: Financials | E44: =IF($A44="","",IF(COUNTIF(ExclList,$D44)>0,"Exclude","Include")) -> Exclude | G44: =IF($A44="","",IF($F44<>"",$F44,$E44)) -> Exclude
A45: CGT | B45: Capital Gearing Trust | C45: GB00BT66KP92 | D45: Financials | E45: =IF($A45="","",IF(COUNTIF(ExclList,$D45)>0,"Exclude","Include")) -> Exclude | G45: =IF($A45="","",IF($F45<>"",$F45,$E45)) -> Exclude
...

Sheet Raw_Fund
A1: key | B1: isin_h | C1: fyear_h | E1: gvkey | F1: isin | G1: conm | H1: fyear | I1: datadate | J1: curcd | K1: revt | L1: ebit | M1: ebitda | N1: ni | O1: oancf | P1: capx | Q1: dltt | R1: dlc | S1: che | T1: mib
A2: =IF($F2="","",$F2&"|"&$H2) | B2: =IF(F2<>"",F2,"") | C2: =IF(H2<>"", H2, "")
A3: =IF($F3="","",$F3&"|"&$H3) | B3: =IF(F3<>"",F3,"") | C3: =IF(H3<>"", H3, "")
A4: =IF($F4="","",$F4&"|"&$H4) | B4: =IF(F4<>"",F4,"") | C4: =IF(H4<>"", H4, "")
A5: =IF($F5="","",$F5&"|"&$H5) | B5: =IF(F5<>"",F5,"") | C5: =IF(H5<>"", H5, "")
A6: =IF($F6="","",$F6&"|"&$H6) | B6: =IF(F6<>"",F6,"") | C6: =IF(H6<>"", H6, "")
A7: =IF($F7="","",$F7&"|"&$H7) | B7: =IF(F7<>"",F7,"") | C7: =IF(H7<>"", H7, "")
A8: =IF($F8="","",$F8&"|"&$H8) | B8: =IF(F8<>"",F8,"") | C8: =IF(H8<>"", H8, "")
A9: =IF($F9="","",$F9&"|"&$H9) | B9: =IF(F9<>"",F9,"") | C9: =IF(H9<>"", H9, "")
A10: =IF($F10="","",$F10&"|"&$H10) | B10: =IF(F10<>"",F10,"") | C10: =IF(H10<>"", H10, "")
A11: =IF($F11="","",$F11&"|"&$H11) | B11: =IF(F11<>"",F11,"") | C11: =IF(H11<>"", H11, "")
A12: =IF($F12="","",$F12&"|"&$H12) | B12: =IF(F12<>"",F12,"") | C12: =IF(H12<>"", H12, "")
A13: =IF($F13="","",$F13&"|"&$H13) | B13: =IF(F13<>"",F13,"") | C13: =IF(H13<>"", H13, "")
... A3000: =IF($F3000="","",$F3000&"|"&$H3000) | B3000: =IF(F3000<>"",F3000,"") | C3000: =IF(H3000<>"", H3000, "")

Sheet Raw_Mkt
A1: isin_h | B1: mcap_gbp_m | D1: gvkey | E1: iid | F1: datadate | G1: isin | H1: conm | I1: prccd | J1: cshoc | K1: curcdd
A2: =IF(G2<>"",G2,"") | B2: =IF($G2="","",IFERROR($I2*$J2/1000000/PriceDiv*_xlfn.XLOOKUP($K2,FX_Ccy,FX_Rate),""))
A3: =IF(G3<>"",G3,"") | B3: =IF($G3="","",IFERROR($I3*$J3/1000000/PriceDiv*_xlfn.XLOOKUP($K3,FX_Ccy,FX_Rate),""))
A4: =IF(G4<>"",G4,"") | B4: =IF($G4="","",IFERROR($I4*$J4/1000000/PriceDiv*_xlfn.XLOOKUP($K4,FX_Ccy,FX_Rate),""))
A5: =IF(G5<>"",G5,"") | B5: =IF($G5="","",IFERROR($I5*$J5/1000000/PriceDiv*_xlfn.XLOOKUP($K5,FX_Ccy,FX_Rate),""))
A6: =IF(G6<>"",G6,"") | B6: =IF($G6="","",IFERROR($I6*$J6/1000000/PriceDiv*_xlfn.XLOOKUP($K6,FX_Ccy,FX_Rate),""))
A7: =IF(G7<>"",G7,"") | B7: =IF($G7="","",IFERROR($I7*$J7/1000000/PriceDiv*_xlfn.XLOOKUP($K7,FX_Ccy,FX_Rate),""))
A8: =IF(G8<>"",G8,"") | B8: =IF($G8="","",IFERROR($I8*$J8/1000000/PriceDiv*_xlfn.XLOOKUP($K8,FX_Ccy,FX_Rate),""))
A9: =IF(G9<>"",G9,"") | B9: =IF($G9="","",IFERROR($I9*$J9/1000000/PriceDiv*_xlfn.XLOOKUP($K9,FX_Ccy,FX_Rate),""))
A10: =IF(G10<>"",G10,"") | B10: =IF($G10="","",IFERROR($I10*$J10/1000000/PriceDiv*_xlfn.XLOOKUP($K10,FX_Ccy,FX_Rate),""))
A11: =IF(G11<>"",G11,"") | B11: =IF($G11="","",IFERROR($I11*$J11/1000000/PriceDiv*_xlfn.XLOOKUP($K11,FX_Ccy,FX_Rate),""))
A12: =IF(G12<>"",G12,"") | B12: =IF($G12="","",IFERROR($I12*$J12/1000000/PriceDiv*_xlfn.XLOOKUP($K12,FX_Ccy,FX_Rate),""))
A13: =IF(G13<>"",G13,"") | B13: =IF($G13="","",IFERROR($I13*$J13/1000000/PriceDiv*_xlfn.XLOOKUP($K13,FX_Ccy,FX_Rate),""))
... A1000: =IF(G1000<>"",G1000,"") | B1000: =IF($G1000="","",IFERROR($I1000*$J1000/1000000/PriceDiv*_xlfn.XLOOKUP($K1000,FX_Ccy,FX_Rate),""))

Sheet Data
E3: WRDS field | G3: curcd | I3: revt | J3: revt | K3: ebit | L3: ebitda | M3: ni | N3: ni | O3: ni | P3: oancf | Q3: oancf | R3: oancf | S3: capx | T3: capx | U3: capx | V3: dltt | W3: dlc | X3: che | Y3: mib
E4: Year offset | I4: 0 | J4: -3 | K4: 0 | L4: 0 | M4: 0 | N4: -1 | O4: -2 | P4: 0 | Q4: -1 | R4: -2 | S4: 0 | T4: -1 | U4: -2
A5: Ticker | B5: Company | C5: ISIN | D5: Sector | E5: Status | F5: Latest FY | G5: Currency | H5: FX to GBP | I5: Revenue FY0 | J5: Revenue FY-3 | K5: EBIT FY0 | L5: EBITDA FY0 | M5: Net income FY0 | N5: Net income FY-1 | O5: Net income FY-2 | P5: CFO FY0 | Q5: CFO FY-1 | R5: CFO FY-2 | S5: Capex FY0 | T5: Capex FY-1 | U5: Capex FY-2 | V5: LT debt | W5: ST debt | X5: Cash | Y5: Minority interest | Z5: Market cap
A6: =IF(Universe!A6<>"",Universe!A6,"") -> 3IN | B6: =IF(Universe!B6<>"",Universe!B6,"") -> 3i Infrastructure | C6: =IF(Universe!C6<>"",Universe!C6,"") -> JE00BF5FX167 | D6: =IF(Universe!D6<>"",Universe!D6,"") -> Financials | E6: =Universe!G6 -> Exclude | F6: =IF($E6<>"Include","",_xlfn.LET(_xlpm.latest,_xlfn.MAXIFS(Raw_Fund!$C:$C,Raw_Fund!$B:$B,Data!$C6),IF(_xlpm.latest=0,"",_xlpm.latest))) | G6: =IF($F6="","",INDEX(Raw_Fund!$E:$AZ,MATCH($C6&"|"&$F6,Raw_Fund!$A:$A,0),MATCH(G$3,Raw_Fund!$E$1:$AZ$1,0))) | H6: =IF($G6="","",_xlfn.XLOOKUP($G6,FX_Ccy,FX_Rate,"Missing FX")) | I6: =_xlfn.LET( _xlpm.rowNo, MATCH($C6&"|"& ($F6+I$4),Raw_Fund!$A:$A,0), _xlpm.colNo, MATCH(I$3,Raw_Fund!$E$1:$AZ$1,0), _xlpm.val, INDEX(Raw_Fund!$E:$AZ,_xlpm.rowNo,_xlpm.colNo), IF(ISNUMBER(_xlpm.val),_xlpm.val*$H6,"")) | J6: =_xlfn.LET( _xlpm.rowNo, MATCH($C6&"|"& ($F6+J$4),Raw_Fund!$A:$A,0), _xlpm.colNo, MATCH(J$3,Raw_Fund!$E$1:$AZ$1,0), _xlpm.val, INDEX(Raw_Fund!$E:$AZ,_xlpm.rowNo,_xlpm.colNo), IF(ISNUMBER(_xlpm.val),_xlpm.val*$H6,"")) | K6: =_xlfn.LET( _xlpm.rowNo, MATCH($C6&"|"& ($F6+K$4),Raw_Fund!$A:$A,0), _xlpm.colNo, MATCH(K$3,Raw_Fund!$E$1:$AZ$1,0), _xlpm.val, INDEX(Raw_Fund!$E:$AZ,_xlpm.rowNo,_xlpm.colNo), IF(ISNUMBER(_xlpm.val),_xlpm.val*$H6,"")) | L6: =_xlfn.LET( _xlpm.rowNo, MATCH($C6&"|"& ($F6+L$4),Raw_Fund!$A:$A,0), _xlpm.colNo, MATCH(L$3,Raw_Fund!$E$1:$AZ$1,0), _xlpm.val, INDEX(Raw_Fund!$E:$AZ,_xlpm.rowNo,_xlpm.colNo), IF(ISNUMBER(_xlpm.val),_xlpm.val*$H6,"")) | M6: =_xlfn.LET( _xlpm.rowNo, MATCH($C6&"|"& ($F6+M$4),Raw_Fund!$A:$A,0), _xlpm.colNo, MATCH(M$3,Raw_Fund!$E$1:$AZ$1,0), _xlpm.val, INDEX(Raw_Fund!$E:$AZ,_xlpm.rowNo,_xlpm.colNo), IF(ISNUMBER(_xlpm.val),_xlpm.val*$H6,"")) | N6: =_xlfn.LET( _xlpm.rowNo, MATCH($C6&"|"& ($F6+N$4),Raw_Fund!$A:$A,0), _xlpm.colNo, MATCH(N$3,Raw_Fund!$E$1:$AZ$1,0), _xlpm.val, INDEX(Raw_Fund!$E:$AZ,_xlpm.rowNo,_xlpm.colNo), IF(ISNUMBER(_xlpm.val),_xlpm.val*$H6,"")) | O6: =_xlfn.LET( _xlpm.rowNo, MATCH($C6&"|"& ($F6+O$4),Raw_Fund!$A:$A,0), _xlpm.colNo, MATCH(O$3,Raw_Fund!$E$1:$AZ$1,0), _xlpm.val, INDEX(Raw_Fund!$E:$AZ,_xlpm.rowNo,_xlpm.colNo), IF(ISNUMBER(_xlpm.val),_xlpm.val*$H6,"")) | P6: =_xlfn.LET( _xlpm.rowNo, MATCH($C6&"|"& ($F6+P$4),Raw_Fund!$A:$A,0), _xlpm.colNo, MATCH(P$3,Raw_Fund!$E$1:$AZ$1,0), _xlpm.val, INDEX(Raw_Fund!$E:$AZ,_xlpm.rowNo,_xlpm.colNo), IF(ISNUMBER(_xlpm.val),_xlpm.val*$H6,"")) | ... Y6: =_xlfn.LET( _xlpm.rowNo, MATCH($C6&"|"& ($F6+Y$4),Raw_Fund!$A:$A,0), _xlpm.colNo, MATCH(Y$3,Raw_Fund!$E$1:$AZ$1,0), _xlpm.val, INDEX(Raw_Fund!$E:$AZ,_xlpm.rowNo,_xlpm.colNo), IF(ISNUMBER(_xlpm.val),_xlpm.val*$H6,"")) | Z6: =IF($E6<>"Include","",_xlfn.XLOOKUP($C6,Raw_Mkt!$A:$A,Raw_Mkt!$B:$B))
A7: =IF(Universe!A7<>"",Universe!A7,"") -> FOUR | B7: =IF(Universe!B7<>"",Universe!B7,"") -> 4imprint | C7: =IF(Universe!C7<>"",Universe!C7,"") -> GB0006640972 | D7: =IF(Universe!D7<>"",Universe!D7,"") -> Consumer Discretionary | E7: =Universe!G7 -> Include | F7: =IF($E7<>"Include","",_xlfn.LET(_xlpm.latest,_xlfn.MAXIFS(Raw_Fund!$C:$C,Raw_Fund!$B:$B,Data!$C7),IF(_xlpm.latest=0,"",_xlpm.latest))) | G7: =IF($F7="","",INDEX(Raw_Fund!$E:$AZ,MATCH($C7&"|"&$F7,Raw_Fund!$A:$A,0),MATCH(G$3,Raw_Fund!$E$1:$AZ$1,0))) | H7: =IF($G7="","",_xlfn.XLOOKUP($G7,FX_Ccy,FX_Rate,"Missing FX")) | I7: =_xlfn.LET( _xlpm.rowNo, MATCH($C7&"|"& ($F7+I$4),Raw_Fund!$A:$A,0), _xlpm.colNo, MATCH(I$3,Raw_Fund!$E$1:$AZ$1,0), _xlpm.val, INDEX(Raw_Fund!$E:$AZ,_xlpm.rowNo,_xlpm.colNo), IF(ISNUMBER(_xlpm.val),_xlpm.val*$H7,"")) | J7: =_xlfn.LET( _xlpm.rowNo, MATCH($C7&"|"& ($F7+J$4),Raw_Fund!$A:$A,0), _xlpm.colNo, MATCH(J$3,Raw_Fund!$E$1:$AZ$1,0), _xlpm.val, INDEX(Raw_Fund!$E:$AZ,_xlpm.rowNo,_xlpm.colNo), IF(ISNUMBER(_xlpm.val),_xlpm.val*$H7,"")) | K7: =_xlfn.LET( _xlpm.rowNo, MATCH($C7&"|"& ($F7+K$4),Raw_Fund!$A:$A,0), _xlpm.colNo, MATCH(K$3,Raw_Fund!$E$1:$AZ$1,0), _xlpm.val, INDEX(Raw_Fund!$E:$AZ,_xlpm.rowNo,_xlpm.colNo), IF(ISNUMBER(_xlpm.val),_xlpm.val*$H7,"")) | L7: =_xlfn.LET( _xlpm.rowNo, MATCH($C7&"|"& ($F7+L$4),Raw_Fund!$A:$A,0), _xlpm.colNo, MATCH(L$3,Raw_Fund!$E$1:$AZ$1,0), _xlpm.val, INDEX(Raw_Fund!$E:$AZ,_xlpm.rowNo,_xlpm.colNo), IF(ISNUMBER(_xlpm.val),_xlpm.val*$H7,"")) | M7: =_xlfn.LET( _xlpm.rowNo, MATCH($C7&"|"& ($F7+M$4),Raw_Fund!$A:$A,0), _xlpm.colNo, MATCH(M$3,Raw_Fund!$E$1:$AZ$1,0), _xlpm.val, INDEX(Raw_Fund!$E:$AZ,_xlpm.rowNo,_xlpm.colNo), IF(ISNUMBER(_xlpm.val),_xlpm.val*$H7,"")) | N7: =_xlfn.LET( _xlpm.rowNo, MATCH($C7&"|"& ($F7+N$4),Raw_Fund!$A:$A,0), _xlpm.colNo, MATCH(N$3,Raw_Fund!$E$1:$AZ$1,0), _xlpm.val, INDEX(Raw_Fund!$E:$AZ,_xlpm.rowNo,_xlpm.colNo), IF(ISNUMBER(_xlpm.val),_xlpm.val*$H7,"")) | O7: =_xlfn.LET( _xlpm.rowNo, MATCH($C7&"|"& ($F7+O$4),Raw_Fund!$A:$A,0), _xlpm.colNo, MATCH(O$3,Raw_Fund!$E$1:$AZ$1,0), _xlpm.val, INDEX(Raw_Fund!$E:$AZ,_xlpm.rowNo,_xlpm.colNo), IF(ISNUMBER(_xlpm.val),_xlpm.val*$H7,"")) | P7: =_xlfn.LET( _xlpm.rowNo, MATCH($C7&"|"& ($F7+P$4),Raw_Fund!$A:$A,0), _xlpm.colNo, MATCH(P$3,Raw_Fund!$E$1:$AZ$1,0), _xlpm.val, INDEX(Raw_Fund!$E:$AZ,_xlpm.rowNo,_xlpm.colNo), IF(ISNUMBER(_xlpm.val),_xlpm.val*$H7,"")) | ... Y7: =_xlfn.LET( _xlpm.rowNo, MATCH($C7&"|"& ($F7+Y$4),Raw_Fund!$A:$A,0), _xlpm.colNo, MATCH(Y$3,Raw_Fund!$E$1:$AZ$1,0), _xlpm.val, INDEX(Raw_Fund!$E:$AZ,_xlpm.rowNo,_xlpm.colNo), IF(ISNUMBER(_xlpm.val),_xlpm.val*$H7,"")) | Z7: =IF($E7<>"Include","",_xlfn.XLOOKUP($C7,Raw_Mkt!$A:$A,Raw_Mkt!$B:$B)) -> #N/A
A8: =IF(Universe!A8<>"",Universe!A8,"") -> AAS | B8: =IF(Universe!B8<>"",Universe!B8,"") -> Aberdeen Asia Focus | C8: =IF(Universe!C8<>"",Universe!C8,"") -> GB00BMF19B58 | D8: =IF(Universe!D8<>"",Universe!D8,"") -> Financials | E8: =Universe!G8 -> Exclude | F8: =IF($E8<>"Include","",_xlfn.LET(_xlpm.latest,_xlfn.MAXIFS(Raw_Fund!$C:$C,Raw_Fund!$B:$B,Data!$C8),IF(_xlpm.latest=0,"",_xlpm.latest))) | G8: =IF($F8="","",INDEX(Raw_Fund!$E:$AZ,MATCH($C8&"|"&$F8,Raw_Fund!$A:$A,0),MATCH(G$3,Raw_Fund!$E$1:$AZ$1,0))) | H8: =IF($G8="","",_xlfn.XLOOKUP($G8,FX_Ccy,FX_Rate,"Missing FX")) | I8: =_xlfn.LET( _xlpm.rowNo, MATCH($C8&"|"& ($F8+I$4),Raw_Fund!$A:$A,0), _xlpm.colNo, MATCH(I$3,Raw_Fund!$E$1:$AZ$1,0), _xlpm.val, INDEX(Raw_Fund!$E:$AZ,_xlpm.rowNo,_xlpm.colNo), IF(ISNUMBER(_xlpm.val),_xlpm.val*$H8,"")) | J8: =_xlfn.LET( _xlpm.rowNo, MATCH($C8&"|"& ($F8+J$4),Raw_Fund!$A:$A,0), _xlpm.colNo, MATCH(J$3,Raw_Fund!$E$1:$AZ$1,0), _xlpm.val, INDEX(Raw_Fund!$E:$AZ,_xlpm.rowNo,_xlpm.colNo), IF(ISNUMBER(_xlpm.val),_xlpm.val*$H8,"")) | K8: =_xlfn.LET( _xlpm.rowNo, MATCH($C8&"|"& ($F8+K$4),Raw_Fund!$A:$A,0), _xlpm.colNo, MATCH(K$3,Raw_Fund!$E$1:$AZ$1,0), _xlpm.val, INDEX(Raw_Fund!$E:$AZ,_xlpm.rowNo,_xlpm.colNo), IF(ISNUMBER(_xlpm.val),_xlpm.val*$H8,"")) | L8: =_xlfn.LET( _xlpm.rowNo, MATCH($C8&"|"& ($F8+L$4),Raw_Fund!$A:$A,0), _xlpm.colNo, MATCH(L$3,Raw_Fund!$E$1:$AZ$1,0), _xlpm.val, INDEX(Raw_Fund!$E:$AZ,_xlpm.rowNo,_xlpm.colNo), IF(ISNUMBER(_xlpm.val),_xlpm.val*$H8,"")) | M8: =_xlfn.LET( _xlpm.rowNo, MATCH($C8&"|"& ($F8+M$4),Raw_Fund!$A:$A,0), _xlpm.colNo, MATCH(M$3,Raw_Fund!$E$1:$AZ$1,0), _xlpm.val, INDEX(Raw_Fund!$E:$AZ,_xlpm.rowNo,_xlpm.colNo), IF(ISNUMBER(_xlpm.val),_xlpm.val*$H8,"")) | N8: =_xlfn.LET( _xlpm.rowNo, MATCH($C8&"|"& ($F8+N$4),Raw_Fund!$A:$A,0), _xlpm.colNo, MATCH(N$3,Raw_Fund!$E$1:$AZ$1,0), _xlpm.val, INDEX(Raw_Fund!$E:$AZ,_xlpm.rowNo,_xlpm.colNo), IF(ISNUMBER(_xlpm.val),_xlpm.val*$H8,"")) | O8: =_xlfn.LET( _xlpm.rowNo, MATCH($C8&"|"& ($F8+O$4),Raw_Fund!$A:$A,0), _xlpm.colNo, MATCH(O$3,Raw_Fund!$E$1:$AZ$1,0), _xlpm.val, INDEX(Raw_Fund!$E:$AZ,_xlpm.rowNo,_xlpm.colNo), IF(ISNUMBER(_xlpm.val),_xlpm.val*$H8,"")) | P8: =_xlfn.LET( _xlpm.rowNo, MATCH($C8&"|"& ($F8+P$4),Raw_Fund!$A:$A,0), _xlpm.colNo, MATCH(P$3,Raw_Fund!$E$1:$AZ$1,0), _xlpm.val, INDEX(Raw_Fund!$E:$AZ,_xlpm.rowNo,_xlpm.colNo), IF(ISNUMBER(_xlpm.val),_xlpm.val*$H8,"")) | ... Y8: =_xlfn.LET( _xlpm.rowNo, MATCH($C8&"|"& ($F8+Y$4),Raw_Fund!$A:$A,0), _xlpm.colNo, MATCH(Y$3,Raw_Fund!$E$1:$AZ$1,0), _xlpm.val, INDEX(Raw_Fund!$E:$AZ,_xlpm.rowNo,_xlpm.colNo), IF(ISNUMBER(_xlpm.val),_xlpm.val*$H8,"")) | Z8: =IF($E8<>"Include","",_xlfn.XLOOKUP($C8,Raw_Mkt!$A:$A,Raw_Mkt!$B:$B))
A9: =IF(Universe!A9<>"",Universe!A9,"") -> ASL | B9: =IF(Universe!B9<>"",Universe!B9,"") -> Aberforth Smaller Companies Trust | C9: =IF(Universe!C9<>"",Universe!C9,"") -> GB0000066554 | D9: =IF(Universe!D9<>"",Universe!D9,"") -> Financials | E9: =Universe!G9 -> Exclude | F9: =IF($E9<>"Include","",_xlfn.LET(_xlpm.latest,_xlfn.MAXIFS(Raw_Fund!$C:$C,Raw_Fund!$B:$B,Data!$C9),IF(_xlpm.latest=0,"",_xlpm.latest))) | G9: =IF($F9="","",INDEX(Raw_Fund!$E:$AZ,MATCH($C9&"|"&$F9,Raw_Fund!$A:$A,0),MATCH(G$3,Raw_Fund!$E$1:$AZ$1,0))) | H9: =IF($G9="","",_xlfn.XLOOKUP($G9,FX_Ccy,FX_Rate,"Missing FX")) | I9: =_xlfn.LET( _xlpm.rowNo, MATCH($C9&"|"& ($F9+I$4),Raw_Fund!$A:$A,0), _xlpm.colNo, MATCH(I$3,Raw_Fund!$E$1:$AZ$1,0), _xlpm.val, INDEX(Raw_Fund!$E:$AZ,_xlpm.rowNo,_xlpm.colNo), IF(ISNUMBER(_xlpm.val),_xlpm.val*$H9,"")) | J9: =_xlfn.LET( _xlpm.rowNo, MATCH($C9&"|"& ($F9+J$4),Raw_Fund!$A:$A,0), _xlpm.colNo, MATCH(J$3,Raw_Fund!$E$1:$AZ$1,0), _xlpm.val, INDEX(Raw_Fund!$E:$AZ,_xlpm.rowNo,_xlpm.colNo), IF(ISNUMBER(_xlpm.val),_xlpm.val*$H9,"")) | K9: =_xlfn.LET( _xlpm.rowNo, MATCH($C9&"|"& ($F9+K$4),Raw_Fund!$A:$A,0), _xlpm.colNo, MATCH(K$3,Raw_Fund!$E$1:$AZ$1,0), _xlpm.val, INDEX(Raw_Fund!$E:$AZ,_xlpm.rowNo,_xlpm.colNo), IF(ISNUMBER(_xlpm.val),_xlpm.val*$H9,"")) | L9: =_xlfn.LET( _xlpm.rowNo, MATCH($C9&"|"& ($F9+L$4),Raw_Fund!$A:$A,0), _xlpm.colNo, MATCH(L$3,Raw_Fund!$E$1:$AZ$1,0), _xlpm.val, INDEX(Raw_Fund!$E:$AZ,_xlpm.rowNo,_xlpm.colNo), IF(ISNUMBER(_xlpm.val),_xlpm.val*$H9,"")) | M9: =_xlfn.LET( _xlpm.rowNo, MATCH($C9&"|"& ($F9+M$4),Raw_Fund!$A:$A,0), _xlpm.colNo, MATCH(M$3,Raw_Fund!$E$1:$AZ$1,0), _xlpm.val, INDEX(Raw_Fund!$E:$AZ,_xlpm.rowNo,_xlpm.colNo), IF(ISNUMBER(_xlpm.val),_xlpm.val*$H9,"")) | N9: =_xlfn.LET( _xlpm.rowNo, MATCH($C9&"|"& ($F9+N$4),Raw_Fund!$A:$A,0), _xlpm.colNo, MATCH(N$3,Raw_Fund!$E$1:$AZ$1,0), _xlpm.val, INDEX(Raw_Fund!$E:$AZ,_xlpm.rowNo,_xlpm.colNo), IF(ISNUMBER(_xlpm.val),_xlpm.val*$H9,"")) | O9: =_xlfn.LET( _xlpm.rowNo, MATCH($C9&"|"& ($F9+O$4),Raw_Fund!$A:$A,0), _xlpm.colNo, MATCH(O$3,Raw_Fund!$E$1:$AZ$1,0), _xlpm.val, INDEX(Raw_Fund!$E:$AZ,_xlpm.rowNo,_xlpm.colNo), IF(ISNUMBER(_xlpm.val),_xlpm.val*$H9,"")) | P9: =_xlfn.LET( _xlpm.rowNo, MATCH($C9&"|"& ($F9+P$4),Raw_Fund!$A:$A,0), _xlpm.colNo, MATCH(P$3,Raw_Fund!$E$1:$AZ$1,0), _xlpm.val, INDEX(Raw_Fund!$E:$AZ,_xlpm.rowNo,_xlpm.colNo), IF(ISNUMBER(_xlpm.val),_xlpm.val*$H9,"")) | ... Y9: =_xlfn.LET( _xlpm.rowNo, MATCH($C9&"|"& ($F9+Y$4),Raw_Fund!$A:$A,0), _xlpm.colNo, MATCH(Y$3,Raw_Fund!$E$1:$AZ$1,0), _xlpm.val, INDEX(Raw_Fund!$E:$AZ,_xlpm.rowNo,_xlpm.colNo), IF(ISNUMBER(_xlpm.val),_xlpm.val*$H9,"")) | Z9: =IF($E9<>"Include","",_xlfn.XLOOKUP($C9,Raw_Mkt!$A:$A,Raw_Mkt!$B:$B))
A10: =IF(Universe!A10<>"",Universe!A10,"") -> AEP | B10: =IF(Universe!B10<>"",Universe!B10,"") -> AEP Plantations | C10: =IF(Universe!C10<>"",Universe!C10,"") -> GB00BWPD4D87 | D10: =IF(Universe!D10<>"",Universe!D10,"") -> Consumer Staples | E10: =Universe!G10 -> Include | F10: =IF($E10<>"Include","",_xlfn.LET(_xlpm.latest,_xlfn.MAXIFS(Raw_Fund!$C:$C,Raw_Fund!$B:$B,Data!$C10),IF(_xlpm.latest=0,"",_xlpm.latest))) | G10: =IF($F10="","",INDEX(Raw_Fund!$E:$AZ,MATCH($C10&"|"&$F10,Raw_Fund!$A:$A,0),MATCH(G$3,Raw_Fund!$E$1:$AZ$1,0))) | H10: =IF($G10="","",_xlfn.XLOOKUP($G10,FX_Ccy,FX_Rate,"Missing FX")) | I10: =_xlfn.LET( _xlpm.rowNo, MATCH($C10&"|"& ($F10+I$4),Raw_Fund!$A:$A,0), _xlpm.colNo, MATCH(I$3,Raw_Fund!$E$1:$AZ$1,0), _xlpm.val, INDEX(Raw_Fund!$E:$AZ,_xlpm.rowNo,_xlpm.colNo), IF(ISNUMBER(_xlpm.val),_xlpm.val*$H10,"")) | J10: =_xlfn.LET( _xlpm.rowNo, MATCH($C10&"|"& ($F10+J$4),Raw_Fund!$A:$A,0), _xlpm.colNo, MATCH(J$3,Raw_Fund!$E$1:$AZ$1,0), _xlpm.val, INDEX(Raw_Fund!$E:$AZ,_xlpm.rowNo,_xlpm.colNo), IF(ISNUMBER(_xlpm.val),_xlpm.val*$H10,"")) | K10: =_xlfn.LET( _xlpm.rowNo, MATCH($C10&"|"& ($F10+K$4),Raw_Fund!$A:$A,0), _xlpm.colNo, MATCH(K$3,Raw_Fund!$E$1:$AZ$1,0), _xlpm.val, INDEX(Raw_Fund!$E:$AZ,_xlpm.rowNo,_xlpm.colNo), IF(ISNUMBER(_xlpm.val),_xlpm.val*$H10,"")) | L10: =_xlfn.LET( _xlpm.rowNo, MATCH($C10&"|"& ($F10+L$4),Raw_Fund!$A:$A,0), _xlpm.colNo, MATCH(L$3,Raw_Fund!$E$1:$AZ$1,0), _xlpm.val, INDEX(Raw_Fund!$E:$AZ,_xlpm.rowNo,_xlpm.colNo), IF(ISNUMBER(_xlpm.val),_xlpm.val*$H10,"")) | M10: =_xlfn.LET( _xlpm.rowNo, MATCH($C10&"|"& ($F10+M$4),Raw_Fund!$A:$A,0), _xlpm.colNo, MATCH(M$3,Raw_Fund!$E$1:$AZ$1,0), _xlpm.val, INDEX(Raw_Fund!$E:$AZ,_xlpm.rowNo,_xlpm.colNo), IF(ISNUMBER(_xlpm.val),_xlpm.val*$H10,"")) | N10: =_xlfn.LET( _xlpm.rowNo, MATCH($C10&"|"& ($F10+N$4),Raw_Fund!$A:$A,0), _xlpm.colNo, MATCH(N$3,Raw_Fund!$E$1:$AZ$1,0), _xlpm.val, INDEX(Raw_Fund!$E:$AZ,_xlpm.rowNo,_xlpm.colNo), IF(ISNUMBER(_xlpm.val),_xlpm.val*$H10,"")) | O10: =_xlfn.LET( _xlpm.rowNo, MATCH($C10&"|"& ($F10+O$4),Raw_Fund!$A:$A,0), _xlpm.colNo, MATCH(O$3,Raw_Fund!$E$1:$AZ$1,0), _xlpm.val, INDEX(Raw_Fund!$E:$AZ,_xlpm.rowNo,_xlpm.colNo), IF(ISNUMBER(_xlpm.val),_xlpm.val*$H10,"")) | P10: =_xlfn.LET( _xlpm.rowNo, MATCH($C10&"|"& ($F10+P$4),Raw_Fund!$A:$A,0), _xlpm.colNo, MATCH(P$3,Raw_Fund!$E$1:$AZ$1,0), _xlpm.val, INDEX(Raw_Fund!$E:$AZ,_xlpm.rowNo,_xlpm.colNo), IF(ISNUMBER(_xlpm.val),_xlpm.val*$H10,"")) | ... Y10: =_xlfn.LET( _xlpm.rowNo, MATCH($C10&"|"& ($F10+Y$4),Raw_Fund!$A:$A,0), _xlpm.colNo, MATCH(Y$3,Raw_Fund!$E$1:$AZ$1,0), _xlpm.val, INDEX(Raw_Fund!$E:$AZ,_xlpm.rowNo,_xlpm.colNo), IF(ISNUMBER(_xlpm.val),_xlpm.val*$H10,"")) | Z10: =IF($E10<>"Include","",_xlfn.XLOOKUP($C10,Raw_Mkt!$A:$A,Raw_Mkt!$B:$B)) -> #N/A
A11: =IF(Universe!A11<>"",Universe!A11,"") -> ALFA | B11: =IF(Universe!B11<>"",Universe!B11,"") -> Alfa Financial Software | C11: =IF(Universe!C11<>"",Universe!C11,"") -> GB00BDHXPG30 | D11: =IF(Universe!D11<>"",Universe!D11,"") -> Technology | E11: =Universe!G11 -> Include | F11: =IF($E11<>"Include","",_xlfn.LET(_xlpm.latest,_xlfn.MAXIFS(Raw_Fund!$C:$C,Raw_Fund!$B:$B,Data!$C11),IF(_xlpm.latest=0,"",_xlpm.latest))) | G11: =IF($F11="","",INDEX(Raw_Fund!$E:$AZ,MATCH($C11&"|"&$F11,Raw_Fund!$A:$A,0),MATCH(G$3,Raw_Fund!$E$1:$AZ$1,0))) | H11: =IF($G11="","",_xlfn.XLOOKUP($G11,FX_Ccy,FX_Rate,"Missing FX")) | I11: =_xlfn.LET( _xlpm.rowNo, MATCH($C11&"|"& ($F11+I$4),Raw_Fund!$A:$A,0), _xlpm.colNo, MATCH(I$3,Raw_Fund!$E$1:$AZ$1,0), _xlpm.val, INDEX(Raw_Fund!$E:$AZ,_xlpm.rowNo,_xlpm.colNo), IF(ISNUMBER(_xlpm.val),_xlpm.val*$H11,"")) | J11: =_xlfn.LET( _xlpm.rowNo, MATCH($C11&"|"& ($F11+J$4),Raw_Fund!$A:$A,0), _xlpm.colNo, MATCH(J$3,Raw_Fund!$E$1:$AZ$1,0), _xlpm.val, INDEX(Raw_Fund!$E:$AZ,_xlpm.rowNo,_xlpm.colNo), IF(ISNUMBER(_xlpm.val),_xlpm.val*$H11,"")) | K11: =_xlfn.LET( _xlpm.rowNo, MATCH($C11&"|"& ($F11+K$4),Raw_Fund!$A:$A,0), _xlpm.colNo, MATCH(K$3,Raw_Fund!$E$1:$AZ$1,0), _xlpm.val, INDEX(Raw_Fund!$E:$AZ,_xlpm.rowNo,_xlpm.colNo), IF(ISNUMBER(_xlpm.val),_xlpm.val*$H11,"")) | L11: =_xlfn.LET( _xlpm.rowNo, MATCH($C11&"|"& ($F11+L$4),Raw_Fund!$A:$A,0), _xlpm.colNo, MATCH(L$3,Raw_Fund!$E$1:$AZ$1,0), _xlpm.val, INDEX(Raw_Fund!$E:$AZ,_xlpm.rowNo,_xlpm.colNo), IF(ISNUMBER(_xlpm.val),_xlpm.val*$H11,"")) | M11: =_xlfn.LET( _xlpm.rowNo, MATCH($C11&"|"& ($F11+M$4),Raw_Fund!$A:$A,0), _xlpm.colNo, MATCH(M$3,Raw_Fund!$E$1:$AZ$1,0), _xlpm.val, INDEX(Raw_Fund!$E:$AZ,_xlpm.rowNo,_xlpm.colNo), IF(ISNUMBER(_xlpm.val),_xlpm.val*$H11,"")) | N11: =_xlfn.LET( _xlpm.rowNo, MATCH($C11&"|"& ($F11+N$4),Raw_Fund!$A:$A,0), _xlpm.colNo, MATCH(N$3,Raw_Fund!$E$1:$AZ$1,0), _xlpm.val, INDEX(Raw_Fund!$E:$AZ,_xlpm.rowNo,_xlpm.colNo), IF(ISNUMBER(_xlpm.val),_xlpm.val*$H11,"")) | O11: =_xlfn.LET( _xlpm.rowNo, MATCH($C11&"|"& ($F11+O$4),Raw_Fund!$A:$A,0), _xlpm.colNo, MATCH(O$3,Raw_Fund!$E$1:$AZ$1,0), _xlpm.val, INDEX(Raw_Fund!$E:$AZ,_xlpm.rowNo,_xlpm.colNo), IF(ISNUMBER(_xlpm.val),_xlpm.val*$H11,"")) | P11: =_xlfn.LET( _xlpm.rowNo, MATCH($C11&"|"& ($F11+P$4),Raw_Fund!$A:$A,0), _xlpm.colNo, MATCH(P$3,Raw_Fund!$E$1:$AZ$1,0), _xlpm.val, INDEX(Raw_Fund!$E:$AZ,_xlpm.rowNo,_xlpm.colNo), IF(ISNUMBER(_xlpm.val),_xlpm.val*$H11,"")) | ... Y11: =_xlfn.LET( _xlpm.rowNo, MATCH($C11&"|"& ($F11+Y$4),Raw_Fund!$A:$A,0), _xlpm.colNo, MATCH(Y$3,Raw_Fund!$E$1:$AZ$1,0), _xlpm.val, INDEX(Raw_Fund!$E:$AZ,_xlpm.rowNo,_xlpm.colNo), IF(ISNUMBER(_xlpm.val),_xlpm.val*$H11,"")) | Z11: =IF($E11<>"Include","",_xlfn.XLOOKUP($C11,Raw_Mkt!$A:$A,Raw_Mkt!$B:$B)) -> #N/A
A12: =IF(Universe!A12<>"",Universe!A12,"") -> ATT | B12: =IF(Universe!B12<>"",Universe!B12,"") -> Allianz Technology Trust | C12: =IF(Universe!C12<>"",Universe!C12,"") -> GB00BNG2M159 | D12: =IF(Universe!D12<>"",Universe!D12,"") -> Financials | E12: =Universe!G12 -> Exclude | F12: =IF($E12<>"Include","",_xlfn.LET(_xlpm.latest,_xlfn.MAXIFS(Raw_Fund!$C:$C,Raw_Fund!$B:$B,Data!$C12),IF(_xlpm.latest=0,"",_xlpm.latest))) | G12: =IF($F12="","",INDEX(Raw_Fund!$E:$AZ,MATCH($C12&"|"&$F12,Raw_Fund!$A:$A,0),MATCH(G$3,Raw_Fund!$E$1:$AZ$1,0))) | H12: =IF($G12="","",_xlfn.XLOOKUP($G12,FX_Ccy,FX_Rate,"Missing FX")) | I12: =_xlfn.LET( _xlpm.rowNo, MATCH($C12&"|"& ($F12+I$4),Raw_Fund!$A:$A,0), _xlpm.colNo, MATCH(I$3,Raw_Fund!$E$1:$AZ$1,0), _xlpm.val, INDEX(Raw_Fund!$E:$AZ,_xlpm.rowNo,_xlpm.colNo), IF(ISNUMBER(_xlpm.val),_xlpm.val*$H12,"")) | J12: =_xlfn.LET( _xlpm.rowNo, MATCH($C12&"|"& ($F12+J$4),Raw_Fund!$A:$A,0), _xlpm.colNo, MATCH(J$3,Raw_Fund!$E$1:$AZ$1,0), _xlpm.val, INDEX(Raw_Fund!$E:$AZ,_xlpm.rowNo,_xlpm.colNo), IF(ISNUMBER(_xlpm.val),_xlpm.val*$H12,"")) | K12: =_xlfn.LET( _xlpm.rowNo, MATCH($C12&"|"& ($F12+K$4),Raw_Fund!$A:$A,0), _xlpm.colNo, MATCH(K$3,Raw_Fund!$E$1:$AZ$1,0), _xlpm.val, INDEX(Raw_Fund!$E:$AZ,_xlpm.rowNo,_xlpm.colNo), IF(ISNUMBER(_xlpm.val),_xlpm.val*$H12,"")) | L12: =_xlfn.LET( _xlpm.rowNo, MATCH($C12&"|"& ($F12+L$4),Raw_Fund!$A:$A,0), _xlpm.colNo, MATCH(L$3,Raw_Fund!$E$1:$AZ$1,0), _xlpm.val, INDEX(Raw_Fund!$E:$AZ,_xlpm.rowNo,_xlpm.colNo), IF(ISNUMBER(_xlpm.val),_xlpm.val*$H12,"")) | M12: =_xlfn.LET( _xlpm.rowNo, MATCH($C12&"|"& ($F12+M$4),Raw_Fund!$A:$A,0), _xlpm.colNo, MATCH(M$3,Raw_Fund!$E$1:$AZ$1,0), _xlpm.val, INDEX(Raw_Fund!$E:$AZ,_xlpm.rowNo,_xlpm.colNo), IF(ISNUMBER(_xlpm.val),_xlpm.val*$H12,"")) | N12: =_xlfn.LET( _xlpm.rowNo, MATCH($C12&"|"& ($F12+N$4),Raw_Fund!$A:$A,0), _xlpm.colNo, MATCH(N$3,Raw_Fund!$E$1:$AZ$1,0), _xlpm.val, INDEX(Raw_Fund!$E:$AZ,_xlpm.rowNo,_xlpm.colNo), IF(ISNUMBER(_xlpm.val),_xlpm.val*$H12,"")) | O12: =_xlfn.LET( _xlpm.rowNo, MATCH($C12&"|"& ($F12+O$4),Raw_Fund!$A:$A,0), _xlpm.colNo, MATCH(O$3,Raw_Fund!$E$1:$AZ$1,0), _xlpm.val, INDEX(Raw_Fund!$E:$AZ,_xlpm.rowNo,_xlpm.colNo), IF(ISNUMBER(_xlpm.val),_xlpm.val*$H12,"")) | P12: =_xlfn.LET( _xlpm.rowNo, MATCH($C12&"|"& ($F12+P$4),Raw_Fund!$A:$A,0), _xlpm.colNo, MATCH(P$3,Raw_Fund!$E$1:$AZ$1,0), _xlpm.val, INDEX(Raw_Fund!$E:$AZ,_xlpm.rowNo,_xlpm.colNo), IF(ISNUMBER(_xlpm.val),_xlpm.val*$H12,"")) | ... Y12: =_xlfn.LET( _xlpm.rowNo, MATCH($C12&"|"& ($F12+Y$4),Raw_Fund!$A:$A,0), _xlpm.colNo, MATCH(Y$3,Raw_Fund!$E$1:$AZ$1,0), _xlpm.val, INDEX(Raw_Fund!$E:$AZ,_xlpm.rowNo,_xlpm.colNo), IF(ISNUMBER(_xlpm.val),_xlpm.val*$H12,"")) | Z12: =IF($E12<>"Include","",_xlfn.XLOOKUP($C12,Raw_Mkt!$A:$A,Raw_Mkt!$B:$B))
A13: =IF(Universe!A13<>"",Universe!A13,"") -> AMRQ | B13: =IF(Universe!B13<>"",Universe!B13,"") -> Amaroq | C13: =IF(Universe!C13<>"",Universe!C13,"") | D13: =IF(Universe!D13<>"",Universe!D13,"") -> Basic Materials | E13: =Universe!G13 -> Exclude | F13: =IF($E13<>"Include","",_xlfn.LET(_xlpm.latest,_xlfn.MAXIFS(Raw_Fund!$C:$C,Raw_Fund!$B:$B,Data!$C13),IF(_xlpm.latest=0,"",_xlpm.latest))) | G13: =IF($F13="","",INDEX(Raw_Fund!$E:$AZ,MATCH($C13&"|"&$F13,Raw_Fund!$A:$A,0),MATCH(G$3,Raw_Fund!$E$1:$AZ$1,0))) | H13: =IF($G13="","",_xlfn.XLOOKUP($G13,FX_Ccy,FX_Rate,"Missing FX")) | I13: =_xlfn.LET( _xlpm.rowNo, MATCH($C13&"|"& ($F13+I$4),Raw_Fund!$A:$A,0), _xlpm.colNo, MATCH(I$3,Raw_Fund!$E$1:$AZ$1,0), _xlpm.val, INDEX(Raw_Fund!$E:$AZ,_xlpm.rowNo,_xlpm.colNo), IF(ISNUMBER(_xlpm.val),_xlpm.val*$H13,"")) | J13: =_xlfn.LET( _xlpm.rowNo, MATCH($C13&"|"& ($F13+J$4),Raw_Fund!$A:$A,0), _xlpm.colNo, MATCH(J$3,Raw_Fund!$E$1:$AZ$1,0), _xlpm.val, INDEX(Raw_Fund!$E:$AZ,_xlpm.rowNo,_xlpm.colNo), IF(ISNUMBER(_xlpm.val),_xlpm.val*$H13,"")) | K13: =_xlfn.LET( _xlpm.rowNo, MATCH($C13&"|"& ($F13+K$4),Raw_Fund!$A:$A,0), _xlpm.colNo, MATCH(K$3,Raw_Fund!$E$1:$AZ$1,0), _xlpm.val, INDEX(Raw_Fund!$E:$AZ,_xlpm.rowNo,_xlpm.colNo), IF(ISNUMBER(_xlpm.val),_xlpm.val*$H13,"")) | L13: =_xlfn.LET( _xlpm.rowNo, MATCH($C13&"|"& ($F13+L$4),Raw_Fund!$A:$A,0), _xlpm.colNo, MATCH(L$3,Raw_Fund!$E$1:$AZ$1,0), _xlpm.val, INDEX(Raw_Fund!$E:$AZ,_xlpm.rowNo,_xlpm.colNo), IF(ISNUMBER(_xlpm.val),_xlpm.val*$H13,"")) | M13: =_xlfn.LET( _xlpm.rowNo, MATCH($C13&"|"& ($F13+M$4),Raw_Fund!$A:$A,0), _xlpm.colNo, MATCH(M$3,Raw_Fund!$E$1:$AZ$1,0), _xlpm.val, INDEX(Raw_Fund!$E:$AZ,_xlpm.rowNo,_xlpm.colNo), IF(ISNUMBER(_xlpm.val),_xlpm.val*$H13,"")) | N13: =_xlfn.LET( _xlpm.rowNo, MATCH($C13&"|"& ($F13+N$4),Raw_Fund!$A:$A,0), _xlpm.colNo, MATCH(N$3,Raw_Fund!$E$1:$AZ$1,0), _xlpm.val, INDEX(Raw_Fund!$E:$AZ,_xlpm.rowNo,_xlpm.colNo), IF(ISNUMBER(_xlpm.val),_xlpm.val*$H13,"")) | O13: =_xlfn.LET( _xlpm.rowNo, MATCH($C13&"|"& ($F13+O$4),Raw_Fund!$A:$A,0), _xlpm.colNo, MATCH(O$3,Raw_Fund!$E$1:$AZ$1,0), _xlpm.val, INDEX(Raw_Fund!$E:$AZ,_xlpm.rowNo,_xlpm.colNo), IF(ISNUMBER(_xlpm.val),_xlpm.val*$H13,"")) | P13: =_xlfn.LET( _xlpm.rowNo, MATCH($C13&"|"& ($F13+P$4),Raw_Fund!$A:$A,0), _xlpm.colNo, MATCH(P$3,Raw_Fund!$E$1:$AZ$1,0), _xlpm.val, INDEX(Raw_Fund!$E:$AZ,_xlpm.rowNo,_xlpm.colNo), IF(ISNUMBER(_xlpm.val),_xlpm.val*$H13,"")) | ... Y13: =_xlfn.LET( _xlpm.rowNo, MATCH($C13&"|"& ($F13+Y$4),Raw_Fund!$A:$A,0), _xlpm.colNo, MATCH(Y$3,Raw_Fund!$E$1:$AZ$1,0), _xlpm.val, INDEX(Raw_Fund!$E:$AZ,_xlpm.rowNo,_xlpm.colNo), IF(ISNUMBER(_xlpm.val),_xlpm.val*$H13,"")) | Z13: =IF($E13<>"Include","",_xlfn.XLOOKUP($C13,Raw_Mkt!$A:$A,Raw_Mkt!$B:$B))
A14: =IF(Universe!A14<>"",Universe!A14,"") -> AO | B14: =IF(Universe!B14<>"",Universe!B14,"") -> AO World | C14: =IF(Universe!C14<>"",Universe!C14,"") -> GB00BJTNFH41 | D14: =IF(Universe!D14<>"",Universe!D14,"") -> Consumer Discretionary | E14: =Universe!G14 -> Include | F14: =IF($E14<>"Include","",_xlfn.LET(_xlpm.latest,_xlfn.MAXIFS(Raw_Fund!$C:$C,Raw_Fund!$B:$B,Data!$C14),IF(_xlpm.latest=0,"",_xlpm.latest))) | G14: =IF($F14="","",INDEX(Raw_Fund!$E:$AZ,MATCH($C14&"|"&$F14,Raw_Fund!$A:$A,0),MATCH(G$3,Raw_Fund!$E$1:$AZ$1,0))) | H14: =IF($G14="","",_xlfn.XLOOKUP($G14,FX_Ccy,FX_Rate,"Missing FX")) | I14: =_xlfn.LET( _xlpm.rowNo, MATCH($C14&"|"& ($F14+I$4),Raw_Fund!$A:$A,0), _xlpm.colNo, MATCH(I$3,Raw_Fund!$E$1:$AZ$1,0), _xlpm.val, INDEX(Raw_Fund!$E:$AZ,_xlpm.rowNo,_xlpm.colNo), IF(ISNUMBER(_xlpm.val),_xlpm.val*$H14,"")) | J14: =_xlfn.LET( _xlpm.rowNo, MATCH($C14&"|"& ($F14+J$4),Raw_Fund!$A:$A,0), _xlpm.colNo, MATCH(J$3,Raw_Fund!$E$1:$AZ$1,0), _xlpm.val, INDEX(Raw_Fund!$E:$AZ,_xlpm.rowNo,_xlpm.colNo), IF(ISNUMBER(_xlpm.val),_xlpm.val*$H14,"")) | K14: =_xlfn.LET( _xlpm.rowNo, MATCH($C14&"|"& ($F14+K$4),Raw_Fund!$A:$A,0), _xlpm.colNo, MATCH(K$3,Raw_Fund!$E$1:$AZ$1,0), _xlpm.val, INDEX(Raw_Fund!$E:$AZ,_xlpm.rowNo,_xlpm.colNo), IF(ISNUMBER(_xlpm.val),_xlpm.val*$H14,"")) | L14: =_xlfn.LET( _xlpm.rowNo, MATCH($C14&"|"& ($F14+L$4),Raw_Fund!$A:$A,0), _xlpm.colNo, MATCH(L$3,Raw_Fund!$E$1:$AZ$1,0), _xlpm.val, INDEX(Raw_Fund!$E:$AZ,_xlpm.rowNo,_xlpm.colNo), IF(ISNUMBER(_xlpm.val),_xlpm.val*$H14,"")) | M14: =_xlfn.LET( _xlpm.rowNo, MATCH($C14&"|"& ($F14+M$4),Raw_Fund!$A:$A,0), _xlpm.colNo, MATCH(M$3,Raw_Fund!$E$1:$AZ$1,0), _xlpm.val, INDEX(Raw_Fund!$E:$AZ,_xlpm.rowNo,_xlpm.colNo), IF(ISNUMBER(_xlpm.val),_xlpm.val*$H14,"")) | N14: =_xlfn.LET( _xlpm.rowNo, MATCH($C14&"|"& ($F14+N$4),Raw_Fund!$A:$A,0), _xlpm.colNo, MATCH(N$3,Raw_Fund!$E$1:$AZ$1,0), _xlpm.val, INDEX(Raw_Fund!$E:$AZ,_xlpm.rowNo,_xlpm.colNo), IF(ISNUMBER(_xlpm.val),_xlpm.val*$H14,"")) | O14: =_xlfn.LET( _xlpm.rowNo, MATCH($C14&"|"& ($F14+O$4),Raw_Fund!$A:$A,0), _xlpm.colNo, MATCH(O$3,Raw_Fund!$E$1:$AZ$1,0), _xlpm.val, INDEX(Raw_Fund!$E:$AZ,_xlpm.rowNo,_xlpm.colNo), IF(ISNUMBER(_xlpm.val),_xlpm.val*$H14,"")) | P14: =_xlfn.LET( _xlpm.rowNo, MATCH($C14&"|"& ($F14+P$4),Raw_Fund!$A:$A,0), _xlpm.colNo, MATCH(P$3,Raw_Fund!$E$1:$AZ$1,0), _xlpm.val, INDEX(Raw_Fund!$E:$AZ,_xlpm.rowNo,_xlpm.colNo), IF(ISNUMBER(_xlpm.val),_xlpm.val*$H14,"")) | ... Y14: =_xlfn.LET( _xlpm.rowNo, MATCH($C14&"|"& ($F14+Y$4),Raw_Fund!$A:$A,0), _xlpm.colNo, MATCH(Y$3,Raw_Fund!$E$1:$AZ$1,0), _xlpm.val, INDEX(Raw_Fund!$E:$AZ,_xlpm.rowNo,_xlpm.colNo), IF(ISNUMBER(_xlpm.val),_xlpm.val*$H14,"")) | Z14: =IF($E14<>"Include","",_xlfn.XLOOKUP($C14,Raw_Mkt!$A:$A,Raw_Mkt!$B:$B)) -> #N/A
A15: =IF(Universe!A15<>"",Universe!A15,"") -> APN | B15: =IF(Universe!B15<>"",Universe!B15,"") -> Applied Nutrition | C15: =IF(Universe!C15<>"",Universe!C15,"") -> GB00BPVDXX64 | D15: =IF(Universe!D15<>"",Universe!D15,"") -> Consumer Staples | E15: =Universe!G15 -> Include | F15: =IF($E15<>"Include","",_xlfn.LET(_xlpm.latest,_xlfn.MAXIFS(Raw_Fund!$C:$C,Raw_Fund!$B:$B,Data!$C15),IF(_xlpm.latest=0,"",_xlpm.latest))) | G15: =IF($F15="","",INDEX(Raw_Fund!$E:$AZ,MATCH($C15&"|"&$F15,Raw_Fund!$A:$A,0),MATCH(G$3,Raw_Fund!$E$1:$AZ$1,0))) | H15: =IF($G15="","",_xlfn.XLOOKUP($G15,FX_Ccy,FX_Rate,"Missing FX")) | I15: =_xlfn.LET( _xlpm.rowNo, MATCH($C15&"|"& ($F15+I$4),Raw_Fund!$A:$A,0), _xlpm.colNo, MATCH(I$3,Raw_Fund!$E$1:$AZ$1,0), _xlpm.val, INDEX(Raw_Fund!$E:$AZ,_xlpm.rowNo,_xlpm.colNo), IF(ISNUMBER(_xlpm.val),_xlpm.val*$H15,"")) | J15: =_xlfn.LET( _xlpm.rowNo, MATCH($C15&"|"& ($F15+J$4),Raw_Fund!$A:$A,0), _xlpm.colNo, MATCH(J$3,Raw_Fund!$E$1:$AZ$1,0), _xlpm.val, INDEX(Raw_Fund!$E:$AZ,_xlpm.rowNo,_xlpm.colNo), IF(ISNUMBER(_xlpm.val),_xlpm.val*$H15,"")) | K15: =_xlfn.LET( _xlpm.rowNo, MATCH($C15&"|"& ($F15+K$4),Raw_Fund!$A:$A,0), _xlpm.colNo, MATCH(K$3,Raw_Fund!$E$1:$AZ$1,0), _xlpm.val, INDEX(Raw_Fund!$E:$AZ,_xlpm.rowNo,_xlpm.colNo), IF(ISNUMBER(_xlpm.val),_xlpm.val*$H15,"")) | L15: =_xlfn.LET( _xlpm.rowNo, MATCH($C15&"|"& ($F15+L$4),Raw_Fund!$A:$A,0), _xlpm.colNo, MATCH(L$3,Raw_Fund!$E$1:$AZ$1,0), _xlpm.val, INDEX(Raw_Fund!$E:$AZ,_xlpm.rowNo,_xlpm.colNo), IF(ISNUMBER(_xlpm.val),_xlpm.val*$H15,"")) | M15: =_xlfn.LET( _xlpm.rowNo, MATCH($C15&"|"& ($F15+M$4),Raw_Fund!$A:$A,0), _xlpm.colNo, MATCH(M$3,Raw_Fund!$E$1:$AZ$1,0), _xlpm.val, INDEX(Raw_Fund!$E:$AZ,_xlpm.rowNo,_xlpm.colNo), IF(ISNUMBER(_xlpm.val),_xlpm.val*$H15,"")) | N15: =_xlfn.LET( _xlpm.rowNo, MATCH($C15&"|"& ($F15+N$4),Raw_Fund!$A:$A,0), _xlpm.colNo, MATCH(N$3,Raw_Fund!$E$1:$AZ$1,0), _xlpm.val, INDEX(Raw_Fund!$E:$AZ,_xlpm.rowNo,_xlpm.colNo), IF(ISNUMBER(_xlpm.val),_xlpm.val*$H15,"")) | O15: =_xlfn.LET( _xlpm.rowNo, MATCH($C15&"|"& ($F15+O$4),Raw_Fund!$A:$A,0), _xlpm.colNo, MATCH(O$3,Raw_Fund!$E$1:$AZ$1,0), _xlpm.val, INDEX(Raw_Fund!$E:$AZ,_xlpm.rowNo,_xlpm.colNo), IF(ISNUMBER(_xlpm.val),_xlpm.val*$H15,"")) | P15: =_xlfn.LET( _xlpm.rowNo, MATCH($C15&"|"& ($F15+P$4),Raw_Fund!$A:$A,0), _xlpm.colNo, MATCH(P$3,Raw_Fund!$E$1:$AZ$1,0), _xlpm.val, INDEX(Raw_Fund!$E:$AZ,_xlpm.rowNo,_xlpm.colNo), IF(ISNUMBER(_xlpm.val),_xlpm.val*$H15,"")) | ... Y15: =_xlfn.LET( _xlpm.rowNo, MATCH($C15&"|"& ($F15+Y$4),Raw_Fund!$A:$A,0), _xlpm.colNo, MATCH(Y$3,Raw_Fund!$E$1:$AZ$1,0), _xlpm.val, INDEX(Raw_Fund!$E:$AZ,_xlpm.rowNo,_xlpm.colNo), IF(ISNUMBER(_xlpm.val),_xlpm.val*$H15,"")) | Z15: =IF($E15<>"Include","",_xlfn.XLOOKUP($C15,Raw_Mkt!$A:$A,Raw_Mkt!$B:$B)) -> #N/A
A16: =IF(Universe!A16<>"",Universe!A16,"") -> ASHM | B16: =IF(Universe!B16<>"",Universe!B16,"") -> Ashmore Group | C16: =IF(Universe!C16<>"",Universe!C16,"") -> GB00B132NW22 | D16: =IF(Universe!D16<>"",Universe!D16,"") -> Financials | E16: =Universe!G16 -> Exclude | G16: =IF($F16="","",INDEX(Raw_Fund!$E:$AZ,MATCH($C16&"|"&$F16,Raw_Fund!$A:$A,0),MATCH(G$3,Raw_Fund!$E$1:$AZ$1,0))) | H16: =IF($G16="","",_xlfn.XLOOKUP($G16,FX_Ccy,FX_Rate,"Missing FX")) | I16: =_xlfn.LET( _xlpm.rowNo, MATCH($C16&"|"& ($F16+I$4),Raw_Fund!$A:$A,0), _xlpm.colNo, MATCH(I$3,Raw_Fund!$E$1:$AZ$1,0), _xlpm.val, INDEX(Raw_Fund!$E:$AZ,_xlpm.rowNo,_xlpm.colNo), IF(ISNUMBER(_xlpm.val),_xlpm.val*$H16,"")) | J16: =_xlfn.LET( _xlpm.rowNo, MATCH($C16&"|"& ($F16+J$4),Raw_Fund!$A:$A,0), _xlpm.colNo, MATCH(J$3,Raw_Fund!$E$1:$AZ$1,0), _xlpm.val, INDEX(Raw_Fund!$E:$AZ,_xlpm.rowNo,_xlpm.colNo), IF(ISNUMBER(_xlpm.val),_xlpm.val*$H16,"")) | K16: =_xlfn.LET( _xlpm.rowNo, MATCH($C16&"|"& ($F16+K$4),Raw_Fund!$A:$A,0), _xlpm.colNo, MATCH(K$3,Raw_Fund!$E$1:$AZ$1,0), _xlpm.val, INDEX(Raw_Fund!$E:$AZ,_xlpm.rowNo,_xlpm.colNo), IF(ISNUMBER(_xlpm.val),_xlpm.val*$H16,"")) | L16: =_xlfn.LET( _xlpm.rowNo, MATCH($C16&"|"& ($F16+L$4),Raw_Fund!$A:$A,0), _xlpm.colNo, MATCH(L$3,Raw_Fund!$E$1:$AZ$1,0), _xlpm.val, INDEX(Raw_Fund!$E:$AZ,_xlpm.rowNo,_xlpm.colNo), IF(ISNUMBER(_xlpm.val),_xlpm.val*$H16,"")) | M16: =_xlfn.LET( _xlpm.rowNo, MATCH($C16&"|"& ($F16+M$4),Raw_Fund!$A:$A,0), _xlpm.colNo, MATCH(M$3,Raw_Fund!$E$1:$AZ$1,0), _xlpm.val, INDEX(Raw_Fund!$E:$AZ,_xlpm.rowNo,_xlpm.colNo), IF(ISNUMBER(_xlpm.val),_xlpm.val*$H16,"")) | N16: =_xlfn.LET( _xlpm.rowNo, MATCH($C16&"|"& ($F16+N$4),Raw_Fund!$A:$A,0), _xlpm.colNo, MATCH(N$3,Raw_Fund!$E$1:$AZ$1,0), _xlpm.val, INDEX(Raw_Fund!$E:$AZ,_xlpm.rowNo,_xlpm.colNo), IF(ISNUMBER(_xlpm.val),_xlpm.val*$H16,"")) | O16: =_xlfn.LET( _xlpm.rowNo, MATCH($C16&"|"& ($F16+O$4),Raw_Fund!$A:$A,0), _xlpm.colNo, MATCH(O$3,Raw_Fund!$E$1:$AZ$1,0), _xlpm.val, INDEX(Raw_Fund!$E:$AZ,_xlpm.rowNo,_xlpm.colNo), IF(ISNUMBER(_xlpm.val),_xlpm.val*$H16,"")) | P16: =_xlfn.LET( _xlpm.rowNo, MATCH($C16&"|"& ($F16+P$4),Raw_Fund!$A:$A,0), _xlpm.colNo, MATCH(P$3,Raw_Fund!$E$1:$AZ$1,0), _xlpm.val, INDEX(Raw_Fund!$E:$AZ,_xlpm.rowNo,_xlpm.colNo), IF(ISNUMBER(_xlpm.val),_xlpm.val*$H16,"")) | ... Y16: =_xlfn.LET( _xlpm.rowNo, MATCH($C16&"|"& ($F16+Y$4),Raw_Fund!$A:$A,0), _xlpm.colNo, MATCH(Y$3,Raw_Fund!$E$1:$AZ$1,0), _xlpm.val, INDEX(Raw_Fund!$E:$AZ,_xlpm.rowNo,_xlpm.colNo), IF(ISNUMBER(_xlpm.val),_xlpm.val*$H16,"")) | Z16: =IF($E16<>"Include","",_xlfn.XLOOKUP($C16,Raw_Mkt!$A:$A,Raw_Mkt!$B:$B))
A17: =IF(Universe!A17<>"",Universe!A17,"") -> AIE | B17: =IF(Universe!B17<>"",Universe!B17,"") -> Ashoka India Equity Investment Trust | C17: =IF(Universe!C17<>"",Universe!C17,"") -> GB00BF50VS41 | D17: =IF(Universe!D17<>"",Universe!D17,"") -> Financials | E17: =Universe!G17 -> Exclude | F17: =IF($E17<>"Include","",_xlfn.LET(_xlpm.latest,_xlfn.MAXIFS(Raw_Fund!$C:$C,Raw_Fund!$B:$B,Data!$C17),IF(_xlpm.latest=0,"",_xlpm.latest))) | G17: =IF($F17="","",INDEX(Raw_Fund!$E:$AZ,MATCH($C17&"|"&$F17,Raw_Fund!$A:$A,0),MATCH(G$3,Raw_Fund!$E$1:$AZ$1,0))) | H17: =IF($G17="","",_xlfn.XLOOKUP($G17,FX_Ccy,FX_Rate,"Missing FX")) | I17: =_xlfn.LET( _xlpm.rowNo, MATCH($C17&"|"& ($F17+I$4),Raw_Fund!$A:$A,0), _xlpm.colNo, MATCH(I$3,Raw_Fund!$E$1:$AZ$1,0), _xlpm.val, INDEX(Raw_Fund!$E:$AZ,_xlpm.rowNo,_xlpm.colNo), IF(ISNUMBER(_xlpm.val),_xlpm.val*$H17,"")) | J17: =_xlfn.LET( _xlpm.rowNo, MATCH($C17&"|"& ($F17+J$4),Raw_Fund!$A:$A,0), _xlpm.colNo, MATCH(J$3,Raw_Fund!$E$1:$AZ$1,0), _xlpm.val, INDEX(Raw_Fund!$E:$AZ,_xlpm.rowNo,_xlpm.colNo), IF(ISNUMBER(_xlpm.val),_xlpm.val*$H17,"")) | K17: =_xlfn.LET( _xlpm.rowNo, MATCH($C17&"|"& ($F17+K$4),Raw_Fund!$A:$A,0), _xlpm.colNo, MATCH(K$3,Raw_Fund!$E$1:$AZ$1,0), _xlpm.val, INDEX(Raw_Fund!$E:$AZ,_xlpm.rowNo,_xlpm.colNo), IF(ISNUMBER(_xlpm.val),_xlpm.val*$H17,"")) | L17: =_xlfn.LET( _xlpm.rowNo, MATCH($C17&"|"& ($F17+L$4),Raw_Fund!$A:$A,0), _xlpm.colNo, MATCH(L$3,Raw_Fund!$E$1:$AZ$1,0), _xlpm.val, INDEX(Raw_Fund!$E:$AZ,_xlpm.rowNo,_xlpm.colNo), IF(ISNUMBER(_xlpm.val),_xlpm.val*$H17,"")) | M17: =_xlfn.LET( _xlpm.rowNo, MATCH($C17&"|"& ($F17+M$4),Raw_Fund!$A:$A,0), _xlpm.colNo, MATCH(M$3,Raw_Fund!$E$1:$AZ$1,0), _xlpm.val, INDEX(Raw_Fund!$E:$AZ,_xlpm.rowNo,_xlpm.colNo), IF(ISNUMBER(_xlpm.val),_xlpm.val*$H17,"")) | N17: =_xlfn.LET( _xlpm.rowNo, MATCH($C17&"|"& ($F17+N$4),Raw_Fund!$A:$A,0), _xlpm.colNo, MATCH(N$3,Raw_Fund!$E$1:$AZ$1,0), _xlpm.val, INDEX(Raw_Fund!$E:$AZ,_xlpm.rowNo,_xlpm.colNo), IF(ISNUMBER(_xlpm.val),_xlpm.val*$H17,"")) | O17: =_xlfn.LET( _xlpm.rowNo, MATCH($C17&"|"& ($F17+O$4),Raw_Fund!$A:$A,0), _xlpm.colNo, MATCH(O$3,Raw_Fund!$E$1:$AZ$1,0), _xlpm.val, INDEX(Raw_Fund!$E:$AZ,_xlpm.rowNo,_xlpm.colNo), IF(ISNUMBER(_xlpm.val),_xlpm.val*$H17,"")) | P17: =_xlfn.LET( _xlpm.rowNo, MATCH($C17&"|"& ($F17+P$4),Raw_Fund!$A:$A,0), _xlpm.colNo, MATCH(P$3,Raw_Fund!$E$1:$AZ$1,0), _xlpm.val, INDEX(Raw_Fund!$E:$AZ,_xlpm.rowNo,_xlpm.colNo), IF(ISNUMBER(_xlpm.val),_xlpm.val*$H17,"")) | ... Y17: =_xlfn.LET( _xlpm.rowNo, MATCH($C17&"|"& ($F17+Y$4),Raw_Fund!$A:$A,0), _xlpm.colNo, MATCH(Y$3,Raw_Fund!$E$1:$AZ$1,0), _xlpm.val, INDEX(Raw_Fund!$E:$AZ,_xlpm.rowNo,_xlpm.colNo), IF(ISNUMBER(_xlpm.val),_xlpm.val*$H17,"")) | Z17: =IF($E17<>"Include","",_xlfn.XLOOKUP($C17,Raw_Mkt!$A:$A,Raw_Mkt!$B:$B))
A18: =IF(Universe!A18<>"",Universe!A18,"") -> ASC | B18: =IF(Universe!B18<>"",Universe!B18,"") -> ASOS | C18: =IF(Universe!C18<>"",Universe!C18,"") -> GB0030927254 | D18: =IF(Universe!D18<>"",Universe!D18,"") -> Consumer Discretionary | E18: =Universe!G18 -> Include | F18: =IF($E18<>"Include","",_xlfn.LET(_xlpm.latest,_xlfn.MAXIFS(Raw_Fund!$C:$C,Raw_Fund!$B:$B,Data!$C18),IF(_xlpm.latest=0,"",_xlpm.latest))) | G18: =IF($F18="","",INDEX(Raw_Fund!$E:$AZ,MATCH($C18&"|"&$F18,Raw_Fund!$A:$A,0),MATCH(G$3,Raw_Fund!$E$1:$AZ$1,0))) | H18: =IF($G18="","",_xlfn.XLOOKUP($G18,FX_Ccy,FX_Rate,"Missing FX")) | I18: =_xlfn.LET( _xlpm.rowNo, MATCH($C18&"|"& ($F18+I$4),Raw_Fund!$A:$A,0), _xlpm.colNo, MATCH(I$3,Raw_Fund!$E$1:$AZ$1,0), _xlpm.val, INDEX(Raw_Fund!$E:$AZ,_xlpm.rowNo,_xlpm.colNo), IF(ISNUMBER(_xlpm.val),_xlpm.val*$H18,"")) | J18: =_xlfn.LET( _xlpm.rowNo, MATCH($C18&"|"& ($F18+J$4),Raw_Fund!$A:$A,0), _xlpm.colNo, MATCH(J$3,Raw_Fund!$E$1:$AZ$1,0), _xlpm.val, INDEX(Raw_Fund!$E:$AZ,_xlpm.rowNo,_xlpm.colNo), IF(ISNUMBER(_xlpm.val),_xlpm.val*$H18,"")) | K18: =_xlfn.LET( _xlpm.rowNo, MATCH($C18&"|"& ($F18+K$4),Raw_Fund!$A:$A,0), _xlpm.colNo, MATCH(K$3,Raw_Fund!$E$1:$AZ$1,0), _xlpm.val, INDEX(Raw_Fund!$E:$AZ,_xlpm.rowNo,_xlpm.colNo), IF(ISNUMBER(_xlpm.val),_xlpm.val*$H18,"")) | L18: =_xlfn.LET( _xlpm.rowNo, MATCH($C18&"|"& ($F18+L$4),Raw_Fund!$A:$A,0), _xlpm.colNo, MATCH(L$3,Raw_Fund!$E$1:$AZ$1,0), _xlpm.val, INDEX(Raw_Fund!$E:$AZ,_xlpm.rowNo,_xlpm.colNo), IF(ISNUMBER(_xlpm.val),_xlpm.val*$H18,"")) | M18: =_xlfn.LET( _xlpm.rowNo, MATCH($C18&"|"& ($F18+M$4),Raw_Fund!$A:$A,0), _xlpm.colNo, MATCH(M$3,Raw_Fund!$E$1:$AZ$1,0), _xlpm.val, INDEX(Raw_Fund!$E:$AZ,_xlpm.rowNo,_xlpm.colNo), IF(ISNUMBER(_xlpm.val),_xlpm.val*$H18,"")) | N18: =_xlfn.LET( _xlpm.rowNo, MATCH($C18&"|"& ($F18+N$4),Raw_Fund!$A:$A,0), _xlpm.colNo, MATCH(N$3,Raw_Fund!$E$1:$AZ$1,0), _xlpm.val, INDEX(Raw_Fund!$E:$AZ,_xlpm.rowNo,_xlpm.colNo), IF(ISNUMBER(_xlpm.val),_xlpm.val*$H18,"")) | O18: =_xlfn.LET( _xlpm.rowNo, MATCH($C18&"|"& ($F18+O$4),Raw_Fund!$A:$A,0), _xlpm.colNo, MATCH(O$3,Raw_Fund!$E$1:$AZ$1,0), _xlpm.val, INDEX(Raw_Fund!$E:$AZ,_xlpm.rowNo,_xlpm.colNo), IF(ISNUMBER(_xlpm.val),_xlpm.val*$H18,"")) | P18: =_xlfn.LET( _xlpm.rowNo, MATCH($C18&"|"& ($F18+P$4),Raw_Fund!$A:$A,0), _xlpm.colNo, MATCH(P$3,Raw_Fund!$E$1:$AZ$1,0), _xlpm.val, INDEX(Raw_Fund!$E:$AZ,_xlpm.rowNo,_xlpm.colNo), IF(ISNUMBER(_xlpm.val),_xlpm.val*$H18,"")) | ... Y18: =_xlfn.LET( _xlpm.rowNo, MATCH($C18&"|"& ($F18+Y$4),Raw_Fund!$A:$A,0), _xlpm.colNo, MATCH(Y$3,Raw_Fund!$E$1:$AZ$1,0), _xlpm.val, INDEX(Raw_Fund!$E:$AZ,_xlpm.rowNo,_xlpm.colNo), IF(ISNUMBER(_xlpm.val),_xlpm.val*$H18,"")) | Z18: =IF($E18<>"Include","",_xlfn.XLOOKUP($C18,Raw_Mkt!$A:$A,Raw_Mkt!$B:$B)) -> #N/A
A19: =IF(Universe!A19<>"",Universe!A19,"") -> ATYM | B19: =IF(Universe!B19<>"",Universe!B19,"") -> Atalaya Mining | C19: =IF(Universe!C19<>"",Universe!C19,"") -> CY0106002112 | D19: =IF(Universe!D19<>"",Universe!D19,"") -> Basic Materials | E19: =Universe!G19 -> Include | F19: =IF($E19<>"Include","",_xlfn.LET(_xlpm.latest,_xlfn.MAXIFS(Raw_Fund!$C:$C,Raw_Fund!$B:$B,Data!$C19),IF(_xlpm.latest=0,"",_xlpm.latest))) | G19: =IF($F19="","",INDEX(Raw_Fund!$E:$AZ,MATCH($C19&"|"&$F19,Raw_Fund!$A:$A,0),MATCH(G$3,Raw_Fund!$E$1:$AZ$1,0))) | H19: =IF($G19="","",_xlfn.XLOOKUP($G19,FX_Ccy,FX_Rate,"Missing FX")) | I19: =_xlfn.LET( _xlpm.rowNo, MATCH($C19&"|"& ($F19+I$4),Raw_Fund!$A:$A,0), _xlpm.colNo, MATCH(I$3,Raw_Fund!$E$1:$AZ$1,0), _xlpm.val, INDEX(Raw_Fund!$E:$AZ,_xlpm.rowNo,_xlpm.colNo), IF(ISNUMBER(_xlpm.val),_xlpm.val*$H19,"")) | J19: =_xlfn.LET( _xlpm.rowNo, MATCH($C19&"|"& ($F19+J$4),Raw_Fund!$A:$A,0), _xlpm.colNo, MATCH(J$3,Raw_Fund!$E$1:$AZ$1,0), _xlpm.val, INDEX(Raw_Fund!$E:$AZ,_xlpm.rowNo,_xlpm.colNo), IF(ISNUMBER(_xlpm.val),_xlpm.val*$H19,"")) | K19: =_xlfn.LET( _xlpm.rowNo, MATCH($C19&"|"& ($F19+K$4),Raw_Fund!$A:$A,0), _xlpm.colNo, MATCH(K$3,Raw_Fund!$E$1:$AZ$1,0), _xlpm.val, INDEX(Raw_Fund!$E:$AZ,_xlpm.rowNo,_xlpm.colNo), IF(ISNUMBER(_xlpm.val),_xlpm.val*$H19,"")) | L19: =_xlfn.LET( _xlpm.rowNo, MATCH($C19&"|"& ($F19+L$4),Raw_Fund!$A:$A,0), _xlpm.colNo, MATCH(L$3,Raw_Fund!$E$1:$AZ$1,0), _xlpm.val, INDEX(Raw_Fund!$E:$AZ,_xlpm.rowNo,_xlpm.colNo), IF(ISNUMBER(_xlpm.val),_xlpm.val*$H19,"")) | M19: =_xlfn.LET( _xlpm.rowNo, MATCH($C19&"|"& ($F19+M$4),Raw_Fund!$A:$A,0), _xlpm.colNo, MATCH(M$3,Raw_Fund!$E$1:$AZ$1,0), _xlpm.val, INDEX(Raw_Fund!$E:$AZ,_xlpm.rowNo,_xlpm.colNo), IF(ISNUMBER(_xlpm.val),_xlpm.val*$H19,"")) | N19: =_xlfn.LET( _xlpm.rowNo, MATCH($C19&"|"& ($F19+N$4),Raw_Fund!$A:$A,0), _xlpm.colNo, MATCH(N$3,Raw_Fund!$E$1:$AZ$1,0), _xlpm.val, INDEX(Raw_Fund!$E:$AZ,_xlpm.rowNo,_xlpm.colNo), IF(ISNUMBER(_xlpm.val),_xlpm.val*$H19,"")) | O19: =_xlfn.LET( _xlpm.rowNo, MATCH($C19&"|"& ($F19+O$4),Raw_Fund!$A:$A,0), _xlpm.colNo, MATCH(O$3,Raw_Fund!$E$1:$AZ$1,0), _xlpm.val, INDEX(Raw_Fund!$E:$AZ,_xlpm.rowNo,_xlpm.colNo), IF(ISNUMBER(_xlpm.val),_xlpm.val*$H19,"")) | P19: =_xlfn.LET( _xlpm.rowNo, MATCH($C19&"|"& ($F19+P$4),Raw_Fund!$A:$A,0), _xlpm.colNo, MATCH(P$3,Raw_Fund!$E$1:$AZ$1,0), _xlpm.val, INDEX(Raw_Fund!$E:$AZ,_xlpm.rowNo,_xlpm.colNo), IF(ISNUMBER(_xlpm.val),_xlpm.val*$H19,"")) | ... Y19: =_xlfn.LET( _xlpm.rowNo, MATCH($C19&"|"& ($F19+Y$4),Raw_Fund!$A:$A,0), _xlpm.colNo, MATCH(Y$3,Raw_Fund!$E$1:$AZ$1,0), _xlpm.val, INDEX(Raw_Fund!$E:$AZ,_xlpm.rowNo,_xlpm.colNo), IF(ISNUMBER(_xlpm.val),_xlpm.val*$H19,"")) | Z19: =IF($E19<>"Include","",_xlfn.XLOOKUP($C19,Raw_Mkt!$A:$A,Raw_Mkt!$B:$B)) -> #N/A
A20: =IF(Universe!A20<>"",Universe!A20,"") -> ATG | B20: =IF(Universe!B20<>"",Universe!B20,"") -> Auction Technology Group | C20: =IF(Universe!C20<>"",Universe!C20,"") -> GB00BMVQDZ64 | D20: =IF(Universe!D20<>"",Universe!D20,"") -> Technology | E20: =Universe!G20 -> Include | F20: =IF($E20<>"Include","",_xlfn.LET(_xlpm.latest,_xlfn.MAXIFS(Raw_Fund!$C:$C,Raw_Fund!$B:$B,Data!$C20),IF(_xlpm.latest=0,"",_xlpm.latest))) | G20: =IF($F20="","",INDEX(Raw_Fund!$E:$AZ,MATCH($C20&"|"&$F20,Raw_Fund!$A:$A,0),MATCH(G$3,Raw_Fund!$E$1:$AZ$1,0))) | H20: =IF($G20="","",_xlfn.XLOOKUP($G20,FX_Ccy,FX_Rate,"Missing FX")) | I20: =_xlfn.LET( _xlpm.rowNo, MATCH($C20&"|"& ($F20+I$4),Raw_Fund!$A:$A,0), _xlpm.colNo, MATCH(I$3,Raw_Fund!$E$1:$AZ$1,0), _xlpm.val, INDEX(Raw_Fund!$E:$AZ,_xlpm.rowNo,_xlpm.colNo), IF(ISNUMBER(_xlpm.val),_xlpm.val*$H20,"")) | J20: =_xlfn.LET( _xlpm.rowNo, MATCH($C20&"|"& ($F20+J$4),Raw_Fund!$A:$A,0), _xlpm.colNo, MATCH(J$3,Raw_Fund!$E$1:$AZ$1,0), _xlpm.val, INDEX(Raw_Fund!$E:$AZ,_xlpm.rowNo,_xlpm.colNo), IF(ISNUMBER(_xlpm.val),_xlpm.val*$H20,"")) | K20: =_xlfn.LET( _xlpm.rowNo, MATCH($C20&"|"& ($F20+K$4),Raw_Fund!$A:$A,0), _xlpm.colNo, MATCH(K$3,Raw_Fund!$E$1:$AZ$1,0), _xlpm.val, INDEX(Raw_Fund!$E:$AZ,_xlpm.rowNo,_xlpm.colNo), IF(ISNUMBER(_xlpm.val),_xlpm.val*$H20,"")) | L20: =_xlfn.LET( _xlpm.rowNo, MATCH($C20&"|"& ($F20+L$4),Raw_Fund!$A:$A,0), _xlpm.colNo, MATCH(L$3,Raw_Fund!$E$1:$AZ$1,0), _xlpm.val, INDEX(Raw_Fund!$E:$AZ,_xlpm.rowNo,_xlpm.colNo), IF(ISNUMBER(_xlpm.val),_xlpm.val*$H20,"")) | M20: =_xlfn.LET( _xlpm.rowNo, MATCH($C20&"|"& ($F20+M$4),Raw_Fund!$A:$A,0), _xlpm.colNo, MATCH(M$3,Raw_Fund!$E$1:$AZ$1,0), _xlpm.val, INDEX(Raw_Fund!$E:$AZ,_xlpm.rowNo,_xlpm.colNo), IF(ISNUMBER(_xlpm.val),_xlpm.val*$H20,"")) | N20: =_xlfn.LET( _xlpm.rowNo, MATCH($C20&"|"& ($F20+N$4),Raw_Fund!$A:$A,0), _xlpm.colNo, MATCH(N$3,Raw_Fund!$E$1:$AZ$1,0), _xlpm.val, INDEX(Raw_Fund!$E:$AZ,_xlpm.rowNo,_xlpm.colNo), IF(ISNUMBER(_xlpm.val),_xlpm.val*$H20,"")) | O20: =_xlfn.LET( _xlpm.rowNo, MATCH($C20&"|"& ($F20+O$4),Raw_Fund!$A:$A,0), _xlpm.colNo, MATCH(O$3,Raw_Fund!$E$1:$AZ$1,0), _xlpm.val, INDEX(Raw_Fund!$E:$AZ,_xlpm.rowNo,_xlpm.colNo), IF(ISNUMBER(_xlpm.val),_xlpm.val*$H20,"")) | P20: =_xlfn.LET( _xlpm.rowNo, MATCH($C20&"|"& ($F20+P$4),Raw_Fund!$A:$A,0), _xlpm.colNo, MATCH(P$3,Raw_Fund!$E$1:$AZ$1,0), _xlpm.val, INDEX(Raw_Fund!$E:$AZ,_xlpm.rowNo,_xlpm.colNo), IF(ISNUMBER(_xlpm.val),_xlpm.val*$H20,"")) | ... Y20: =_xlfn.LET( _xlpm.rowNo, MATCH($C20&"|"& ($F20+Y$4),Raw_Fund!$A:$A,0), _xlpm.colNo, MATCH(Y$3,Raw_Fund!$E$1:$AZ$1,0), _xlpm.val, INDEX(Raw_Fund!$E:$AZ,_xlpm.rowNo,_xlpm.colNo), IF(ISNUMBER(_xlpm.val),_xlpm.val*$H20,"")) | Z20: =IF($E20<>"Include","",_xlfn.XLOOKUP($C20,Raw_Mkt!$A:$A,Raw_Mkt!$B:$B)) -> #N/A
A21: =IF(Universe!A21<>"",Universe!A21,"") -> AGT | B21: =IF(Universe!B21<>"",Universe!B21,"") -> AVI Global Trust | C21: =IF(Universe!C21<>"",Universe!C21,"") -> GB00BLH3CY60 | D21: =IF(Universe!D21<>"",Universe!D21,"") -> Financials | E21: =Universe!G21 -> Exclude | F21: =IF($E21<>"Include","",_xlfn.LET(_xlpm.latest,_xlfn.MAXIFS(Raw_Fund!$C:$C,Raw_Fund!$B:$B,Data!$C21),IF(_xlpm.latest=0,"",_xlpm.latest))) | G21: =IF($F21="","",INDEX(Raw_Fund!$E:$AZ,MATCH($C21&"|"&$F21,Raw_Fund!$A:$A,0),MATCH(G$3,Raw_Fund!$E$1:$AZ$1,0))) | H21: =IF($G21="","",_xlfn.XLOOKUP($G21,FX_Ccy,FX_Rate,"Missing FX")) | I21: =_xlfn.LET( _xlpm.rowNo, MATCH($C21&"|"& ($F21+I$4),Raw_Fund!$A:$A,0), _xlpm.colNo, MATCH(I$3,Raw_Fund!$E$1:$AZ$1,0), _xlpm.val, INDEX(Raw_Fund!$E:$AZ,_xlpm.rowNo,_xlpm.colNo), IF(ISNUMBER(_xlpm.val),_xlpm.val*$H21,"")) | J21: =_xlfn.LET( _xlpm.rowNo, MATCH($C21&"|"& ($F21+J$4),Raw_Fund!$A:$A,0), _xlpm.colNo, MATCH(J$3,Raw_Fund!$E$1:$AZ$1,0), _xlpm.val, INDEX(Raw_Fund!$E:$AZ,_xlpm.rowNo,_xlpm.colNo), IF(ISNUMBER(_xlpm.val),_xlpm.val*$H21,"")) | K21: =_xlfn.LET( _xlpm.rowNo, MATCH($C21&"|"& ($F21+K$4),Raw_Fund!$A:$A,0), _xlpm.colNo, MATCH(K$3,Raw_Fund!$E$1:$AZ$1,0), _xlpm.val, INDEX(Raw_Fund!$E:$AZ,_xlpm.rowNo,_xlpm.colNo), IF(ISNUMBER(_xlpm.val),_xlpm.val*$H21,"")) | L21: =_xlfn.LET( _xlpm.rowNo, MATCH($C21&"|"& ($F21+L$4),Raw_Fund!$A:$A,0), _xlpm.colNo, MATCH(L$3,Raw_Fund!$E$1:$AZ$1,0), _xlpm.val, INDEX(Raw_Fund!$E:$AZ,_xlpm.rowNo,_xlpm.colNo), IF(ISNUMBER(_xlpm.val),_xlpm.val*$H21,"")) | M21: =_xlfn.LET( _xlpm.rowNo, MATCH($C21&"|"& ($F21+M$4),Raw_Fund!$A:$A,0), _xlpm.colNo, MATCH(M$3,Raw_Fund!$E$1:$AZ$1,0), _xlpm.val, INDEX(Raw_Fund!$E:$AZ,_xlpm.rowNo,_xlpm.colNo), IF(ISNUMBER(_xlpm.val),_xlpm.val*$H21,"")) | N21: =_xlfn.LET( _xlpm.rowNo, MATCH($C21&"|"& ($F21+N$4),Raw_Fund!$A:$A,0), _xlpm.colNo, MATCH(N$3,Raw_Fund!$E$1:$AZ$1,0), _xlpm.val, INDEX(Raw_Fund!$E:$AZ,_xlpm.rowNo,_xlpm.colNo), IF(ISNUMBER(_xlpm.val),_xlpm.val*$H21,"")) | O21: =_xlfn.LET( _xlpm.rowNo, MATCH($C21&"|"& ($F21+O$4),Raw_Fund!$A:$A,0), _xlpm.colNo, MATCH(O$3,Raw_Fund!$E$1:$AZ$1,0), _xlpm.val, INDEX(Raw_Fund!$E:$AZ,_xlpm.rowNo,_xlpm.colNo), IF(ISNUMBER(_xlpm.val),_xlpm.val*$H21,"")) | P21: =_xlfn.LET( _xlpm.rowNo, MATCH($C21&"|"& ($F21+P$4),Raw_Fund!$A:$A,0), _xlpm.colNo, MATCH(P$3,Raw_Fund!$E$1:$AZ$1,0), _xlpm.val, INDEX(Raw_Fund!$E:$AZ,_xlpm.rowNo,_xlpm.colNo), IF(ISNUMBER(_xlpm.val),_xlpm.val*$H21,"")) | ... Y21: =_xlfn.LET( _xlpm.rowNo, MATCH($C21&"|"& ($F21+Y$4),Raw_Fund!$A:$A,0), _xlpm.colNo, MATCH(Y$3,Raw_Fund!$E$1:$AZ$1,0), _xlpm.val, INDEX(Raw_Fund!$E:$AZ,_xlpm.rowNo,_xlpm.colNo), IF(ISNUMBER(_xlpm.val),_xlpm.val*$H21,"")) | Z21: =IF($E21<>"Include","",_xlfn.XLOOKUP($C21,Raw_Mkt!$A:$A,Raw_Mkt!$B:$B))
A22: =IF(Universe!A22<>"",Universe!A22,"") -> AVON | B22: =IF(Universe!B22<>"",Universe!B22,"") -> Avon Technologies | C22: =IF(Universe!C22<>"",Universe!C22,"") -> GB0000667013 | D22: =IF(Universe!D22<>"",Universe!D22,"") -> Industrials | E22: =Universe!G22 -> Include | F22: =IF($E22<>"Include","",_xlfn.LET(_xlpm.latest,_xlfn.MAXIFS(Raw_Fund!$C:$C,Raw_Fund!$B:$B,Data!$C22),IF(_xlpm.latest=0,"",_xlpm.latest))) | G22: =IF($F22="","",INDEX(Raw_Fund!$E:$AZ,MATCH($C22&"|"&$F22,Raw_Fund!$A:$A,0),MATCH(G$3,Raw_Fund!$E$1:$AZ$1,0))) | H22: =IF($G22="","",_xlfn.XLOOKUP($G22,FX_Ccy,FX_Rate,"Missing FX")) | I22: =_xlfn.LET( _xlpm.rowNo, MATCH($C22&"|"& ($F22+I$4),Raw_Fund!$A:$A,0), _xlpm.colNo, MATCH(I$3,Raw_Fund!$E$1:$AZ$1,0), _xlpm.val, INDEX(Raw_Fund!$E:$AZ,_xlpm.rowNo,_xlpm.colNo), IF(ISNUMBER(_xlpm.val),_xlpm.val*$H22,"")) | J22: =_xlfn.LET( _xlpm.rowNo, MATCH($C22&"|"& ($F22+J$4),Raw_Fund!$A:$A,0), _xlpm.colNo, MATCH(J$3,Raw_Fund!$E$1:$AZ$1,0), _xlpm.val, INDEX(Raw_Fund!$E:$AZ,_xlpm.rowNo,_xlpm.colNo), IF(ISNUMBER(_xlpm.val),_xlpm.val*$H22,"")) | K22: =_xlfn.LET( _xlpm.rowNo, MATCH($C22&"|"& ($F22+K$4),Raw_Fund!$A:$A,0), _xlpm.colNo, MATCH(K$3,Raw_Fund!$E$1:$AZ$1,0), _xlpm.val, INDEX(Raw_Fund!$E:$AZ,_xlpm.rowNo,_xlpm.colNo), IF(ISNUMBER(_xlpm.val),_xlpm.val*$H22,"")) | L22: =_xlfn.LET( _xlpm.rowNo, MATCH($C22&"|"& ($F22+L$4),Raw_Fund!$A:$A,0), _xlpm.colNo, MATCH(L$3,Raw_Fund!$E$1:$AZ$1,0), _xlpm.val, INDEX(Raw_Fund!$E:$AZ,_xlpm.rowNo,_xlpm.colNo), IF(ISNUMBER(_xlpm.val),_xlpm.val*$H22,"")) | M22: =_xlfn.LET( _xlpm.rowNo, MATCH($C22&"|"& ($F22+M$4),Raw_Fund!$A:$A,0), _xlpm.colNo, MATCH(M$3,Raw_Fund!$E$1:$AZ$1,0), _xlpm.val, INDEX(Raw_Fund!$E:$AZ,_xlpm.rowNo,_xlpm.colNo), IF(ISNUMBER(_xlpm.val),_xlpm.val*$H22,"")) | N22: =_xlfn.LET( _xlpm.rowNo, MATCH($C22&"|"& ($F22+N$4),Raw_Fund!$A:$A,0), _xlpm.colNo, MATCH(N$3,Raw_Fund!$E$1:$AZ$1,0), _xlpm.val, INDEX(Raw_Fund!$E:$AZ,_xlpm.rowNo,_xlpm.colNo), IF(ISNUMBER(_xlpm.val),_xlpm.val*$H22,"")) | O22: =_xlfn.LET( _xlpm.rowNo, MATCH($C22&"|"& ($F22+O$4),Raw_Fund!$A:$A,0), _xlpm.colNo, MATCH(O$3,Raw_Fund!$E$1:$AZ$1,0), _xlpm.val, INDEX(Raw_Fund!$E:$AZ,_xlpm.rowNo,_xlpm.colNo), IF(ISNUMBER(_xlpm.val),_xlpm.val*$H22,"")) | P22: =_xlfn.LET( _xlpm.rowNo, MATCH($C22&"|"& ($F22+P$4),Raw_Fund!$A:$A,0), _xlpm.colNo, MATCH(P$3,Raw_Fund!$E$1:$AZ$1,0), _xlpm.val, INDEX(Raw_Fund!$E:$AZ,_xlpm.rowNo,_xlpm.colNo), IF(ISNUMBER(_xlpm.val),_xlpm.val*$H22,"")) | ... Y22: =_xlfn.LET( _xlpm.rowNo, MATCH($C22&"|"& ($F22+Y$4),Raw_Fund!$A:$A,0), _xlpm.colNo, MATCH(Y$3,Raw_Fund!$E$1:$AZ$1,0), _xlpm.val, INDEX(Raw_Fund!$E:$AZ,_xlpm.rowNo,_xlpm.colNo), IF(ISNUMBER(_xlpm.val),_xlpm.val*$H22,"")) | Z22: =IF($E22<>"Include","",_xlfn.XLOOKUP($C22,Raw_Mkt!$A:$A,Raw_Mkt!$B:$B)) -> #N/A
